{
  "cookies": {
    "_cfuvid": "3tlgzf4PCD2GZaG6.H1HMtx6eH3ruM9c3JZF1pmeUqI-1747940891960-0.0.1.1-604800000"
  },
  "created_at": "2025-05-22T19:08:11.899531+00:00",
  "elapsed": 0.579815,
  "encoding": "utf-8",
  "headers": {
    "CF-Cache-Status": "MISS",
    "CF-Ray": "943e99cbe8411fc3-QRO",
    "Cache-Control": "max-age=0, private, must-revalidate",
    "Connection": "keep-alive",
    "Content-Encoding": "gzip",
    "Content-Type": "application/json",
    "Date": "Thu, 22 May 2025 19:08:11 GMT",
    "ETag": "W/\"f4c22d53bd560cf5b35b594b80858553\"",
    "Link": "<https://gitlab.com/api/v4/groups/2524164/epics/115/issues?epic_iid=115&id=2524164&page=1&per_page=20>; rel=\"first\", <https://gitlab.com/api/v4/groups/2524164/epics/115/issues?epic_iid=115&id=2524164&page=1&per_page=20>; rel=\"last\"",
    "Server": "cloudflare",
    "Set-Cookie": "_cfuvid=3tlgzf4PCD2GZaG6.H1HMtx6eH3ruM9c3JZF1pmeUqI-1747940891960-0.0.1.1-604800000; path=/; domain=.gitlab.com; HttpOnly; Secure; SameSite=None",
    "Strict-Transport-Security": "max-age=31536000",
    "Transfer-Encoding": "chunked",
    "Vary": "Origin, Accept-Encoding",
    "content-security-policy": "default-src 'none'",
    "gitlab-lb": "haproxy-main-29-lb-gprd",
    "gitlab-sv": "api-gke-us-east1-c",
    "nel": "{\"max_age\": 0}",
    "referrer-policy": "strict-origin-when-cross-origin",
    "x-content-type-options": "nosniff",
    "x-frame-options": "SAMEORIGIN",
    "x-gitlab-meta": "{\"correlation_id\":\"8750cb8791a51fc339363eb16ea8a01e\",\"version\":\"1\"}",
    "x-next-page": "",
    "x-page": "1",
    "x-per-page": "20",
    "x-prev-page": "",
    "x-request-id": "8750cb8791a51fc339363eb16ea8a01e",
    "x-runtime": "0.354773",
    "x-total": "11",
    "x-total-pages": "1"
  },
  "reason": "OK",
  "request": {
    "body": "",
    "headers": {
      "Accept": "*/*",
      "Accept-Encoding": "gzip, deflate",
      "Connection": "keep-alive",
      "Private-Token": "REDACTED",
      "User-Agent": "sample-tap-gitlab/[could not be detected]"
    },
    "method": "GET",
    "url": "https://gitlab.com/api/v4/groups/2524164/epics/115/issues"
  },
  "status_code": 200,
  "url": "https://gitlab.com/api/v4/groups/2524164/epics/115/issues",
  "_decoded_content": [
    {
      "id": 109130679,
      "iid": 3530,
      "project_id": 7603319,
      "title": "Windows pytest Failures",
      "description": "There's a number of pytest tests that are skipped for Windows. You can grep the code for this issue number to find them.  (at the time of writing this issue the code is https://gitlab.com/meltano/meltano/-/merge_requests/2639 ) \n\nI think success for this issue is that most of the Windows Tests are passing, and any individual tests that are left marked as \"skipped\" either have an individual issue in for them or are acceptable to ignore and the reason is put in pytest.",
      "state": "closed",
      "created_at": "2022-05-25T22:23:27.166Z",
      "updated_at": "2022-05-30T13:41:56.310Z",
      "closed_at": "2022-05-30T13:41:56.289Z",
      "closed_by": {
        "id": 11629953,
        "username": "MeltyBot",
        "public_email": "",
        "name": "Melty Bot",
        "state": "active",
        "locked": false,
        "avatar_url": "https://gitlab.com/uploads/-/system/user/avatar/11629953/avatar.png",
        "web_url": "https://gitlab.com/MeltyBot"
      },
      "labels": [
        "Windows Support",
        "kind::Bug",
        "valuestream::Meltano"
      ],
      "milestone": {
        "id": 2136620,
        "iid": 176,
        "group_id": 2524164,
        "title": "Staging",
        "description": "",
        "state": "active",
        "created_at": "2021-07-07T19:00:49.676Z",
        "updated_at": "2021-07-07T19:00:49.676Z",
        "due_date": null,
        "start_date": null,
        "expired": false,
        "web_url": "https://gitlab.com/groups/meltano/-/milestones/176"
      },
      "assignees": [],
      "author": {
        "id": 5562019,
        "username": "vischous",
        "public_email": "",
        "name": "Derek Visch",
        "state": "active",
        "locked": false,
        "avatar_url": "https://gitlab.com/uploads/-/system/user/avatar/5562019/avatar.png",
        "web_url": "https://gitlab.com/vischous"
      },
      "type": "ISSUE",
      "assignee": null,
      "user_notes_count": 1,
      "merge_requests_count": 0,
      "upvotes": 0,
      "downvotes": 0,
      "due_date": null,
      "confidential": false,
      "discussion_locked": null,
      "issue_type": "issue",
      "web_url": "https://gitlab.com/meltano/meltano/-/issues/3530",
      "time_stats": {
        "time_estimate": 0,
        "total_time_spent": 0,
        "human_time_estimate": null,
        "human_total_time_spent": null
      },
      "task_completion_status": {
        "count": 0,
        "completed_count": 0
      },
      "weight": null,
      "blocking_issues_count": 0,
      "has_tasks": true,
      "task_status": "0 of 0 checklist items completed",
      "_links": {
        "self": "https://gitlab.com/api/v4/projects/7603319/issues/3530",
        "notes": "https://gitlab.com/api/v4/projects/7603319/issues/3530/notes",
        "award_emoji": "https://gitlab.com/api/v4/projects/7603319/issues/3530/award_emoji",
        "project": "https://gitlab.com/api/v4/projects/7603319",
        "closed_as_duplicate_of": null
      },
      "references": {
        "short": "#3530",
        "relative": "#3530",
        "full": "meltano/meltano#3530"
      },
      "severity": "UNKNOWN",
      "moved_to_id": null,
      "imported": false,
      "imported_from": "none",
      "service_desk_reply_to": null,
      "epic_iid": 115,
      "epic": {
        "id": 329384,
        "iid": 115,
        "title": "Meltano on Windows",
        "url": "/groups/meltano/-/epics/115",
        "group_id": 2524164,
        "human_readable_end_date": "May 31, 2022",
        "human_readable_timestamp": "<strong>Past due</strong>"
      },
      "iteration": null,
      "health_status": null,
      "epic_issue_id": 1392277,
      "relative_position": -5130
    },
    {
      "id": 108466375,
      "iid": 3483,
      "project_id": 7603319,
      "title": "windows: pipx installed meltano can not find meltano dependency example gunicorn",
      "description": "### What is the current *bug* behavior?\npipx installed meltano is not able to find dependent packages like gunicorn.  \n\n\n\n### What is the expected *correct* behavior?\nI am expecting pipx meltano to be able to find dependent packages like an it does in a manually created python enviroment with pip installed meltano.\n\n\n\n### Steps to reproduce\npipx meltano FileNotFound steps\n```\npipx install meltano\nmeltano init meltano-demo\ncd meltano-demo\nmeltano ui\n```\npython venv pip meltano file found ran and crashes on ModuleNotFoundError\n```\npython -m venv .\\.venv\\meltano\n.\\.venv\\meltano\\Scripts\\Activate.ps1\npip install meltano\ncd meltano-demo\nmeltano ui\n```\n\n\n\n\n### Relevant logs and/or screenshots\n![image](/uploads/e854f517695d0bb0e5f56fe21b45ab8b/image.png)\n\n![image](/uploads/f7692de557c40c2ce830d05a4178d258/image.png)\n\n\n\n### Possible fixes\nThe fix is that in the meltano_invoker it searches for exact file name in the active python environment but in windows these files have a .exe at the end so the file search fails.  The command is run hoping it is in the path but the only path pipx give it to the users .local\\bin that does not contain all the dependent packages so the application doesn't run. \n\n\n\n### Further regression test\n_Ensure we automatically catch similar issues in the future_\n\n- [ ] Write additional adequate test cases and submit test results\n- [ ] Test results should be reviewed by a person from the team",
      "state": "closed",
      "created_at": "2022-05-12T17:30:19.770Z",
      "updated_at": "2022-05-19T20:31:11.601Z",
      "closed_at": "2022-05-19T20:31:11.427Z",
      "closed_by": {
        "id": 22132,
        "username": "pandemicsyn",
        "public_email": "",
        "name": "Florian",
        "state": "active",
        "locked": false,
        "avatar_url": "https://secure.gravatar.com/avatar/4233db8f5d3b6e2b9871c627d6fdc49a3714d39122a09a8e71d08405b191b4b2?s=80&d=identicon",
        "web_url": "https://gitlab.com/pandemicsyn"
      },
      "labels": [
        "Windows Support",
        "kind::Bug",
        "valuestream::Meltano"
      ],
      "milestone": {
        "id": 2136620,
        "iid": 176,
        "group_id": 2524164,
        "title": "Staging",
        "description": "",
        "state": "active",
        "created_at": "2021-07-07T19:00:49.676Z",
        "updated_at": "2021-07-07T19:00:49.676Z",
        "due_date": null,
        "start_date": null,
        "expired": false,
        "web_url": "https://gitlab.com/groups/meltano/-/milestones/176"
      },
      "assignees": [],
      "author": {
        "id": 11232982,
        "username": "BuzzCutNorman",
        "public_email": "",
        "name": "Dan Norman",
        "state": "active",
        "locked": false,
        "avatar_url": "https://secure.gravatar.com/avatar/d0643a73d2d930c7ffa73eac21c983e4cbe0139b151b85906c9c3beed15f0905?s=80&d=identicon",
        "web_url": "https://gitlab.com/BuzzCutNorman"
      },
      "type": "ISSUE",
      "assignee": null,
      "user_notes_count": 0,
      "merge_requests_count": 1,
      "upvotes": 0,
      "downvotes": 0,
      "due_date": null,
      "confidential": false,
      "discussion_locked": null,
      "issue_type": "issue",
      "web_url": "https://gitlab.com/meltano/meltano/-/issues/3483",
      "time_stats": {
        "time_estimate": 0,
        "total_time_spent": 0,
        "human_time_estimate": null,
        "human_total_time_spent": null
      },
      "task_completion_status": {
        "count": 2,
        "completed_count": 0
      },
      "weight": null,
      "blocking_issues_count": 0,
      "has_tasks": false,
      "_links": {
        "self": "https://gitlab.com/api/v4/projects/7603319/issues/3483",
        "notes": "https://gitlab.com/api/v4/projects/7603319/issues/3483/notes",
        "award_emoji": "https://gitlab.com/api/v4/projects/7603319/issues/3483/award_emoji",
        "project": "https://gitlab.com/api/v4/projects/7603319",
        "closed_as_duplicate_of": null
      },
      "references": {
        "short": "#3483",
        "relative": "#3483",
        "full": "meltano/meltano#3483"
      },
      "severity": "UNKNOWN",
      "moved_to_id": null,
      "imported": false,
      "imported_from": "none",
      "service_desk_reply_to": null,
      "epic_iid": 115,
      "epic": {
        "id": 329384,
        "iid": 115,
        "title": "Meltano on Windows",
        "url": "/groups/meltano/-/epics/115",
        "group_id": 2524164,
        "human_readable_end_date": "May 31, 2022",
        "human_readable_timestamp": "<strong>Past due</strong>"
      },
      "iteration": null,
      "health_status": null,
      "epic_issue_id": 1361173,
      "relative_position": -4617
    },
    {
      "id": 107427992,
      "iid": 3450,
      "project_id": 7603319,
      "title": "\"Install on Windows\" section in the docs",
      "description": "",
      "state": "closed",
      "created_at": "2022-04-28T20:39:02.510Z",
      "updated_at": "2022-05-30T13:34:02.796Z",
      "closed_at": "2022-05-30T13:34:02.770Z",
      "closed_by": {
        "id": 11629953,
        "username": "MeltyBot",
        "public_email": "",
        "name": "Melty Bot",
        "state": "active",
        "locked": false,
        "avatar_url": "https://gitlab.com/uploads/-/system/user/avatar/11629953/avatar.png",
        "web_url": "https://gitlab.com/MeltyBot"
      },
      "labels": [
        "Documentation",
        "OKR: Improve New User Experience",
        "Windows Support",
        "flow::Review",
        "kind::Bug",
        "valuestream::Meltano"
      ],
      "milestone": {
        "id": 2351599,
        "iid": 209,
        "group_id": 2524164,
        "title": "May 2022",
        "description": "",
        "state": "active",
        "created_at": "2021-11-29T21:38:23.665Z",
        "updated_at": "2021-11-29T21:38:23.665Z",
        "due_date": "2022-05-31",
        "start_date": "2022-05-01",
        "expired": true,
        "web_url": "https://gitlab.com/groups/meltano/-/milestones/209"
      },
      "assignees": [
        {
          "id": 5562019,
          "username": "vischous",
          "public_email": "",
          "name": "Derek Visch",
          "state": "active",
          "locked": false,
          "avatar_url": "https://gitlab.com/uploads/-/system/user/avatar/5562019/avatar.png",
          "web_url": "https://gitlab.com/vischous"
        }
      ],
      "author": {
        "id": 4809760,
        "username": "aaronsteers",
        "public_email": "aaronsteers@gmail.com",
        "name": "AJ Steers",
        "state": "active",
        "locked": false,
        "avatar_url": "https://secure.gravatar.com/avatar/a2595480c83e2879745276d7beca618e489d7df97677ed44888fd6f0f50efb29?s=80&d=identicon",
        "web_url": "https://gitlab.com/aaronsteers"
      },
      "type": "ISSUE",
      "assignee": {
        "id": 5562019,
        "username": "vischous",
        "public_email": "",
        "name": "Derek Visch",
        "state": "active",
        "locked": false,
        "avatar_url": "https://gitlab.com/uploads/-/system/user/avatar/5562019/avatar.png",
        "web_url": "https://gitlab.com/vischous"
      },
      "user_notes_count": 1,
      "merge_requests_count": 1,
      "upvotes": 0,
      "downvotes": 0,
      "due_date": null,
      "confidential": false,
      "discussion_locked": null,
      "issue_type": "issue",
      "web_url": "https://gitlab.com/meltano/meltano/-/issues/3450",
      "time_stats": {
        "time_estimate": 0,
        "total_time_spent": 0,
        "human_time_estimate": null,
        "human_total_time_spent": null
      },
      "task_completion_status": {
        "count": 0,
        "completed_count": 0
      },
      "weight": null,
      "blocking_issues_count": 0,
      "has_tasks": true,
      "task_status": "",
      "_links": {
        "self": "https://gitlab.com/api/v4/projects/7603319/issues/3450",
        "notes": "https://gitlab.com/api/v4/projects/7603319/issues/3450/notes",
        "award_emoji": "https://gitlab.com/api/v4/projects/7603319/issues/3450/award_emoji",
        "project": "https://gitlab.com/api/v4/projects/7603319",
        "closed_as_duplicate_of": null
      },
      "references": {
        "short": "#3450",
        "relative": "#3450",
        "full": "meltano/meltano#3450"
      },
      "severity": "UNKNOWN",
      "moved_to_id": null,
      "imported": false,
      "imported_from": "none",
      "service_desk_reply_to": null,
      "epic_iid": 115,
      "epic": {
        "id": 329384,
        "iid": 115,
        "title": "Meltano on Windows",
        "url": "/groups/meltano/-/epics/115",
        "group_id": 2524164,
        "human_readable_end_date": "May 31, 2022",
        "human_readable_timestamp": "<strong>Past due</strong>"
      },
      "iteration": {
        "id": 56416,
        "iid": 56,
        "sequence": 3,
        "group_id": 2524164,
        "title": null,
        "description": null,
        "state": 3,
        "created_at": "2022-05-13T20:04:48.839Z",
        "updated_at": "2022-05-30T00:05:02.370Z",
        "start_date": "2022-05-23",
        "due_date": "2022-05-29",
        "web_url": "https://gitlab.com/groups/meltano/-/iterations/56416"
      },
      "health_status": null,
      "epic_issue_id": 1329456,
      "relative_position": -4104
    },
    {
      "id": 106360778,
      "iid": 3390,
      "project_id": 7603319,
      "title": "meltano init not creating DB",
      "description": "This happens on windows, I'd assume not other OS's, the DB is not initting. `meltano, version 1.99.0` I'm not certain this is new behavior it could have been around all this time and I just missed putting an issue in (seems unlikely but it's possible) \n\n1. Run `meltano init test`\n1. See output below\n```\nPS C:\\code> meltano --log-level=debug init test-issue\nCreated test\nCreating project files...\n  test/\n   |-- meltano.yml\n   |-- README.md\n   |-- requirements.txt\n   |-- output\\.gitignore\n   |-- .gitignore\n   |-- model\\.gitkeep\n   |-- extract\\.gitkeep\n   |-- load\\.gitkeep\n   |-- transform\\.gitkeep\n   |-- analyze\\.gitkeep\n   |-- notebook\\.gitkeep\n   |-- orchestrate\\.gitkeep\nCreating system database...2022-04-08T19:54:04.823778Z [info     ] DB connection failed. Will retry after 5s. Attempt 1/3\n2022-04-08T19:54:09.841274Z [info     ] DB connection failed. Will retry after 5s. Attempt 2/3\n2022-04-08T19:54:14.857067Z [info     ] DB connection failed. Will retry after 5s. Attempt 3/3\n2022-04-08T19:54:19.872743Z [error    ] Could not connect to the Database. Max retries exceeded.\n(sqlite3.OperationalError) unable to open database file\n(Background on this error at: https://sqlalche.me/e/14/e3q8)\n\nPS C:\\code> meltano --version\nmeltano, version 1.99.0\n```",
      "state": "closed",
      "created_at": "2022-04-08T19:56:50.795Z",
      "updated_at": "2022-04-20T18:05:40.054Z",
      "closed_at": "2022-04-20T18:05:39.973Z",
      "closed_by": {
        "id": 22132,
        "username": "pandemicsyn",
        "public_email": "",
        "name": "Florian",
        "state": "active",
        "locked": false,
        "avatar_url": "https://secure.gravatar.com/avatar/4233db8f5d3b6e2b9871c627d6fdc49a3714d39122a09a8e71d08405b191b4b2?s=80&d=identicon",
        "web_url": "https://gitlab.com/pandemicsyn"
      },
      "labels": [
        "Windows Support",
        "flow::Review",
        "kind::Bug",
        "urgency::high",
        "valuestream::Meltano"
      ],
      "milestone": {
        "id": 2351598,
        "iid": 208,
        "group_id": 2524164,
        "title": "April 2022",
        "description": "",
        "state": "closed",
        "created_at": "2021-11-29T21:38:06.797Z",
        "updated_at": "2022-05-02T14:53:27.097Z",
        "due_date": "2022-04-30",
        "start_date": "2022-04-01",
        "expired": true,
        "web_url": "https://gitlab.com/groups/meltano/-/milestones/208"
      },
      "assignees": [],
      "author": {
        "id": 5562019,
        "username": "vischous",
        "public_email": "",
        "name": "Derek Visch",
        "state": "active",
        "locked": false,
        "avatar_url": "https://gitlab.com/uploads/-/system/user/avatar/5562019/avatar.png",
        "web_url": "https://gitlab.com/vischous"
      },
      "type": "ISSUE",
      "assignee": null,
      "user_notes_count": 14,
      "merge_requests_count": 1,
      "upvotes": 0,
      "downvotes": 0,
      "due_date": null,
      "confidential": false,
      "discussion_locked": null,
      "issue_type": "issue",
      "web_url": "https://gitlab.com/meltano/meltano/-/issues/3390",
      "time_stats": {
        "time_estimate": 0,
        "total_time_spent": 0,
        "human_time_estimate": null,
        "human_total_time_spent": null
      },
      "task_completion_status": {
        "count": 0,
        "completed_count": 0
      },
      "weight": 2,
      "blocking_issues_count": 0,
      "has_tasks": true,
      "task_status": "0 of 0 checklist items completed",
      "_links": {
        "self": "https://gitlab.com/api/v4/projects/7603319/issues/3390",
        "notes": "https://gitlab.com/api/v4/projects/7603319/issues/3390/notes",
        "award_emoji": "https://gitlab.com/api/v4/projects/7603319/issues/3390/award_emoji",
        "project": "https://gitlab.com/api/v4/projects/7603319",
        "closed_as_duplicate_of": null
      },
      "references": {
        "short": "#3390",
        "relative": "#3390",
        "full": "meltano/meltano#3390"
      },
      "severity": "UNKNOWN",
      "moved_to_id": null,
      "imported": false,
      "imported_from": "none",
      "service_desk_reply_to": null,
      "epic_iid": 115,
      "epic": {
        "id": 329384,
        "iid": 115,
        "title": "Meltano on Windows",
        "url": "/groups/meltano/-/epics/115",
        "group_id": 2524164,
        "human_readable_end_date": "May 31, 2022",
        "human_readable_timestamp": "<strong>Past due</strong>"
      },
      "iteration": null,
      "health_status": null,
      "epic_issue_id": 1289963,
      "relative_position": -3591
    },
    {
      "id": 106186526,
      "iid": 3383,
      "project_id": 7603319,
      "title": "Meltano UI does not work on Windows (Gunicorn is incompatible)",
      "description": "Gunicorn is used in Meltano UI, and simply does not support Windows.\n\nWe could evaluate similar alternatives to Gunicorn which would support Windows, and thereby allow windows users to also run `meltano ui`. One such option is Waitress:\n\n- https://betterprogramming.pub/introduction-to-waitress-a-wsgi-server-for-python-2-and-3-c77e20cb292b\n- https://docs.pylonsproject.org/projects/waitress/en/stable/",
      "state": "closed",
      "created_at": "2022-04-06T15:12:03.265Z",
      "updated_at": "2022-05-27T01:20:04.895Z",
      "closed_at": "2022-05-27T01:16:51.389Z",
      "closed_by": {
        "id": 22132,
        "username": "pandemicsyn",
        "public_email": "",
        "name": "Florian",
        "state": "active",
        "locked": false,
        "avatar_url": "https://secure.gravatar.com/avatar/4233db8f5d3b6e2b9871c627d6fdc49a3714d39122a09a8e71d08405b191b4b2?s=80&d=identicon",
        "web_url": "https://gitlab.com/pandemicsyn"
      },
      "labels": [
        "OKR: Improve New User Experience",
        "Office Hours::Up Next",
        "Windows Support",
        "kind::Bug",
        "valuestream::Meltano"
      ],
      "milestone": {
        "id": 2351599,
        "iid": 209,
        "group_id": 2524164,
        "title": "May 2022",
        "description": "",
        "state": "active",
        "created_at": "2021-11-29T21:38:23.665Z",
        "updated_at": "2021-11-29T21:38:23.665Z",
        "due_date": "2022-05-31",
        "start_date": "2022-05-01",
        "expired": true,
        "web_url": "https://gitlab.com/groups/meltano/-/milestones/209"
      },
      "assignees": [
        {
          "id": 5562019,
          "username": "vischous",
          "public_email": "",
          "name": "Derek Visch",
          "state": "active",
          "locked": false,
          "avatar_url": "https://gitlab.com/uploads/-/system/user/avatar/5562019/avatar.png",
          "web_url": "https://gitlab.com/vischous"
        }
      ],
      "author": {
        "id": 4809760,
        "username": "aaronsteers",
        "public_email": "aaronsteers@gmail.com",
        "name": "AJ Steers",
        "state": "active",
        "locked": false,
        "avatar_url": "https://secure.gravatar.com/avatar/a2595480c83e2879745276d7beca618e489d7df97677ed44888fd6f0f50efb29?s=80&d=identicon",
        "web_url": "https://gitlab.com/aaronsteers"
      },
      "type": "ISSUE",
      "assignee": {
        "id": 5562019,
        "username": "vischous",
        "public_email": "",
        "name": "Derek Visch",
        "state": "active",
        "locked": false,
        "avatar_url": "https://gitlab.com/uploads/-/system/user/avatar/5562019/avatar.png",
        "web_url": "https://gitlab.com/vischous"
      },
      "user_notes_count": 7,
      "merge_requests_count": 1,
      "upvotes": 2,
      "downvotes": 0,
      "due_date": null,
      "confidential": false,
      "discussion_locked": null,
      "issue_type": "issue",
      "web_url": "https://gitlab.com/meltano/meltano/-/issues/3383",
      "time_stats": {
        "time_estimate": 0,
        "total_time_spent": 0,
        "human_time_estimate": null,
        "human_total_time_spent": null
      },
      "task_completion_status": {
        "count": 0,
        "completed_count": 0
      },
      "weight": null,
      "blocking_issues_count": 0,
      "has_tasks": true,
      "task_status": "0 of 0 checklist items completed",
      "_links": {
        "self": "https://gitlab.com/api/v4/projects/7603319/issues/3383",
        "notes": "https://gitlab.com/api/v4/projects/7603319/issues/3383/notes",
        "award_emoji": "https://gitlab.com/api/v4/projects/7603319/issues/3383/award_emoji",
        "project": "https://gitlab.com/api/v4/projects/7603319",
        "closed_as_duplicate_of": null
      },
      "references": {
        "short": "#3383",
        "relative": "#3383",
        "full": "meltano/meltano#3383"
      },
      "severity": "UNKNOWN",
      "moved_to_id": null,
      "imported": false,
      "imported_from": "none",
      "service_desk_reply_to": null,
      "epic_iid": 115,
      "epic": {
        "id": 329384,
        "iid": 115,
        "title": "Meltano on Windows",
        "url": "/groups/meltano/-/epics/115",
        "group_id": 2524164,
        "human_readable_end_date": "May 31, 2022",
        "human_readable_timestamp": "<strong>Past due</strong>"
      },
      "iteration": {
        "id": 56416,
        "iid": 56,
        "sequence": 3,
        "group_id": 2524164,
        "title": null,
        "description": null,
        "state": 3,
        "created_at": "2022-05-13T20:04:48.839Z",
        "updated_at": "2022-05-30T00:05:02.370Z",
        "start_date": "2022-05-23",
        "due_date": "2022-05-29",
        "web_url": "https://gitlab.com/groups/meltano/-/iterations/56416"
      },
      "health_status": null,
      "epic_issue_id": 1289314,
      "relative_position": -3078
    },
    {
      "id": 92230218,
      "iid": 2901,
      "project_id": 7603319,
      "title": "SIGTERM handling not compatible with Windows",
      "description": "As described in #2743, the SIGTERM handling is not currently supported on Windows.\n\nHere is a possible explanation with workaround: https://stackoverflow.com/questions/26061814/signal-handling-in-windows",
      "state": "closed",
      "created_at": "2021-08-18T22:02:56.170Z",
      "updated_at": "2022-05-30T09:35:31.396Z",
      "closed_at": "2022-05-30T09:35:31.364Z",
      "closed_by": {
        "id": 11629953,
        "username": "MeltyBot",
        "public_email": "",
        "name": "Melty Bot",
        "state": "active",
        "locked": false,
        "avatar_url": "https://gitlab.com/uploads/-/system/user/avatar/11629953/avatar.png",
        "web_url": "https://gitlab.com/MeltyBot"
      },
      "labels": [
        "OKR: Improve New User Experience",
        "Windows Support",
        "kind::Bug",
        "valuestream::Meltano"
      ],
      "milestone": {
        "id": 2351599,
        "iid": 209,
        "group_id": 2524164,
        "title": "May 2022",
        "description": "",
        "state": "active",
        "created_at": "2021-11-29T21:38:23.665Z",
        "updated_at": "2021-11-29T21:38:23.665Z",
        "due_date": "2022-05-31",
        "start_date": "2022-05-01",
        "expired": true,
        "web_url": "https://gitlab.com/groups/meltano/-/milestones/209"
      },
      "assignees": [
        {
          "id": 5562019,
          "username": "vischous",
          "public_email": "",
          "name": "Derek Visch",
          "state": "active",
          "locked": false,
          "avatar_url": "https://gitlab.com/uploads/-/system/user/avatar/5562019/avatar.png",
          "web_url": "https://gitlab.com/vischous"
        }
      ],
      "author": {
        "id": 4809760,
        "username": "aaronsteers",
        "public_email": "aaronsteers@gmail.com",
        "name": "AJ Steers",
        "state": "active",
        "locked": false,
        "avatar_url": "https://secure.gravatar.com/avatar/a2595480c83e2879745276d7beca618e489d7df97677ed44888fd6f0f50efb29?s=80&d=identicon",
        "web_url": "https://gitlab.com/aaronsteers"
      },
      "type": "ISSUE",
      "assignee": {
        "id": 5562019,
        "username": "vischous",
        "public_email": "",
        "name": "Derek Visch",
        "state": "active",
        "locked": false,
        "avatar_url": "https://gitlab.com/uploads/-/system/user/avatar/5562019/avatar.png",
        "web_url": "https://gitlab.com/vischous"
      },
      "user_notes_count": 2,
      "merge_requests_count": 0,
      "upvotes": 0,
      "downvotes": 0,
      "due_date": null,
      "confidential": false,
      "discussion_locked": null,
      "issue_type": "issue",
      "web_url": "https://gitlab.com/meltano/meltano/-/issues/2901",
      "time_stats": {
        "time_estimate": 0,
        "total_time_spent": 0,
        "human_time_estimate": null,
        "human_total_time_spent": null
      },
      "task_completion_status": {
        "count": 0,
        "completed_count": 0
      },
      "weight": 4,
      "blocking_issues_count": 0,
      "has_tasks": true,
      "task_status": "0 of 0 checklist items completed",
      "_links": {
        "self": "https://gitlab.com/api/v4/projects/7603319/issues/2901",
        "notes": "https://gitlab.com/api/v4/projects/7603319/issues/2901/notes",
        "award_emoji": "https://gitlab.com/api/v4/projects/7603319/issues/2901/award_emoji",
        "project": "https://gitlab.com/api/v4/projects/7603319",
        "closed_as_duplicate_of": null
      },
      "references": {
        "short": "#2901",
        "relative": "#2901",
        "full": "meltano/meltano#2901"
      },
      "severity": "UNKNOWN",
      "moved_to_id": null,
      "imported": false,
      "imported_from": "none",
      "service_desk_reply_to": null,
      "epic_iid": 115,
      "epic": {
        "id": 329384,
        "iid": 115,
        "title": "Meltano on Windows",
        "url": "/groups/meltano/-/epics/115",
        "group_id": 2524164,
        "human_readable_end_date": "May 31, 2022",
        "human_readable_timestamp": "<strong>Past due</strong>"
      },
      "iteration": {
        "id": 56416,
        "iid": 56,
        "sequence": 3,
        "group_id": 2524164,
        "title": null,
        "description": null,
        "state": 3,
        "created_at": "2022-05-13T20:04:48.839Z",
        "updated_at": "2022-05-30T00:05:02.370Z",
        "start_date": "2022-05-23",
        "due_date": "2022-05-29",
        "web_url": "https://gitlab.com/groups/meltano/-/iterations/56416"
      },
      "health_status": null,
      "epic_issue_id": 777807,
      "relative_position": -513
    },
    {
      "id": 92229880,
      "iid": 2900,
      "project_id": 7603319,
      "title": "Migrate STDOUT/STDIN exchanges from asynchio pipes to queues",
      "description": "As discussed in #2743 and this comment (https://gitlab.com/meltano/meltano/-/issues/2743#note_569087851), asyncio queues can be used in place of pipes to send data between processes.\n\n\ncc @pandemicsyn \n\n--------------\n\nFrom our code:\n\nhttps://gitlab.com/meltano/meltano/-/blob/c58cb8e56be1b8bae0eefcb6ba906e3c2010852e/src/meltano/core/logging/output_logger.py#L201\n\n```python\n   async def _read_from_fd(self, read_fd):\n        # Since we're redirecting our own stdout and stderr output,\n        # the line length limit can be arbitrarily large.\n        line_length_limit = 1024 * 1024 * 1024  # 1 GiB\n\n        reader = asyncio.StreamReader(limit=line_length_limit)\n        read_protocol = asyncio.StreamReaderProtocol(reader)\n\n        loop = asyncio.get_event_loop()\n        read_transport, _ = await loop.connect_read_pipe(  # <<<<\n            lambda: read_protocol, os.fdopen(read_fd)\n        )\n\n        await capture_subprocess_output(reader, self)\n```\n\nFrom https://docs.python.org/3/library/asyncio-platforms.html#windows:\n\n> SelectorEventLoop has the following limitations:\n> \n> - ...\n> - Pipes are not supported, so the loop.connect_read_pipe() and loop.connect_write_pipe() methods are not implemented.\n\n--------------\n\nAlternative implementation using queues from [here](https://gitlab.com/meltano/meltano/-/issues/2743#note_568237854):\n\n```python\nasync def first_pipe_cmd(command, queue, cwd=\".\"):\n   proc = await asyncio.create_subprocess_shell(\n           command,\n           stdout=asyncio.subprocess.PIPE,\n           #stderr=asyncio.subprocess.PIPE, \n           cwd=cwd)\n  #await asyncio.wait(_outstream_handler(proc.stderr, \"stderr\", \"first_pipe_cmd\")) #Broken at the moment\n   data =\"first\"\n   while data:\n       data = await proc.stdout.readline()\n       line = data.decode()\n       if data: await queue.put(line)\n       logging.info(f\"Queue data for processes, data is {line}\")\n   logging.info(\"First piped process has completed\")\n```",
      "state": "closed",
      "created_at": "2021-08-18T21:44:57.603Z",
      "updated_at": "2022-05-30T09:35:23.829Z",
      "closed_at": "2022-05-30T09:35:23.809Z",
      "closed_by": {
        "id": 11629953,
        "username": "MeltyBot",
        "public_email": "",
        "name": "Melty Bot",
        "state": "active",
        "locked": false,
        "avatar_url": "https://gitlab.com/uploads/-/system/user/avatar/11629953/avatar.png",
        "web_url": "https://gitlab.com/MeltyBot"
      },
      "labels": [
        "OKR: Improve New User Experience",
        "Windows Support",
        "kind::Feature",
        "valuestream::Meltano"
      ],
      "milestone": {
        "id": 797629,
        "iid": 42,
        "group_id": 2524164,
        "title": "Backlog",
        "description": "As a start, I think it would be good to prioritize based on:\r\n- urgency of getting feedback\r\n- relative implementation difficulty\r\n- symbiotic relationships between issues",
        "state": "active",
        "created_at": "2019-02-21T14:50:28.741Z",
        "updated_at": "2019-02-21T14:50:28.741Z",
        "due_date": null,
        "start_date": "2019-02-25",
        "expired": false,
        "web_url": "https://gitlab.com/groups/meltano/-/milestones/42"
      },
      "assignees": [],
      "author": {
        "id": 4809760,
        "username": "aaronsteers",
        "public_email": "aaronsteers@gmail.com",
        "name": "AJ Steers",
        "state": "active",
        "locked": false,
        "avatar_url": "https://secure.gravatar.com/avatar/a2595480c83e2879745276d7beca618e489d7df97677ed44888fd6f0f50efb29?s=80&d=identicon",
        "web_url": "https://gitlab.com/aaronsteers"
      },
      "type": "ISSUE",
      "assignee": null,
      "user_notes_count": 13,
      "merge_requests_count": 0,
      "upvotes": 0,
      "downvotes": 0,
      "due_date": null,
      "confidential": false,
      "discussion_locked": null,
      "issue_type": "issue",
      "web_url": "https://gitlab.com/meltano/meltano/-/issues/2900",
      "time_stats": {
        "time_estimate": 0,
        "total_time_spent": 0,
        "human_time_estimate": null,
        "human_total_time_spent": null
      },
      "task_completion_status": {
        "count": 0,
        "completed_count": 0
      },
      "weight": null,
      "blocking_issues_count": 0,
      "has_tasks": true,
      "task_status": "0 of 0 checklist items completed",
      "_links": {
        "self": "https://gitlab.com/api/v4/projects/7603319/issues/2900",
        "notes": "https://gitlab.com/api/v4/projects/7603319/issues/2900/notes",
        "award_emoji": "https://gitlab.com/api/v4/projects/7603319/issues/2900/award_emoji",
        "project": "https://gitlab.com/api/v4/projects/7603319",
        "closed_as_duplicate_of": null
      },
      "references": {
        "short": "#2900",
        "relative": "#2900",
        "full": "meltano/meltano#2900"
      },
      "severity": "UNKNOWN",
      "moved_to_id": null,
      "imported": false,
      "imported_from": "none",
      "service_desk_reply_to": null,
      "epic_iid": 115,
      "epic": {
        "id": 329384,
        "iid": 115,
        "title": "Meltano on Windows",
        "url": "/groups/meltano/-/epics/115",
        "group_id": 2524164,
        "human_readable_end_date": "May 31, 2022",
        "human_readable_timestamp": "<strong>Past due</strong>"
      },
      "iteration": null,
      "health_status": null,
      "epic_issue_id": 778819,
      "relative_position": 0
    },
    {
      "id": 86543574,
      "iid": 2743,
      "project_id": 7603319,
      "title": "Meltano ELT fails when running on native windows",
      "description": "(needs the Windows Support tag)\n\nTo replicate on windows\n\n```\nPS C:\\code\\meltano-windowstest2> meltano --version\nmeltano, version 1.73.0\nPS C:\\code\\meltano-windowstest2> $Env:PYTHONASYNCIODEBUG=1\nPS C:\\code\\meltano-windowstest2> meltano --log-level=debug elt tap-csv target-csv\n```\n\nOutput from Meltano command (Note that the data in this instance actually does properly flow to my output file, but the program is stuck and I have to signal the process (CTRL+C) to stop the program, which then leads to the exceptions being dumped. Also note that I tried to dump the output to a log file instead of my command prompt output but that didn't include the exception information from asyncio (`>log 2>&1`) after the CTRL+C was sent so this is just a straight copy from my powershell window instead. \n\nThe exceptions not being printed is probably caused by `loop.set_exception_handler` not being utilized. That could probably be a separate issue, and would help some folks with debugging asyncio. I only stumbled on this because I mess up code all the time and was upset I couldn't see RunTime Exceptions.\n\n**Output from a \"successful\" run**\n```\nPS C:\\code\\meltano-windowstest2> meltano --version\nmeltano, version 1.73.0\nPS C:\\code\\meltano-windowstest2> $Env:PYTHONASYNCIODEBUG=1\nPS C:\\code\\meltano-windowstest2> meltano --log-level=debug elt tap-csv target-csv\n[2021-05-05 14:12:21,076] [12024|MainThread|root] [DEBUG] Creating engine <meltano.core.project.Project object at 0x000001A94C457970>@sqlite:///C:\\code\\meltano-windowstest2/.meltano/meltano.db\n[2021-05-05 14:12:21,110] [12024|MainThread|asyncio] [DEBUG] Using proactor: IocpProactor\nmeltano | DEBUG Starting new HTTPS connection (1): www.meltano.com:443\nmeltano | DEBUG https://www.meltano.com:443 \"GET /discovery.yml?project_id=1281de93-235e-4185-85ce-2b3555a991ae HTTP/1.1\" 200 103053\nmeltano | DEBUG Variable '$MELTANO_LOAD_SCHEMA' is missing from the environment.\nmeltano          | INFO Running extract & load...\nmeltano          | DEBUG Created configuration at C:\\code\\meltano-windowstest2\\.meltano\\run\\elt\\2021-05-05T181221--tap-csv--target-csv\\1aec1d92-7fb9-4e86-885f-f71ddf7f6db1\\tap.config.json\nmeltano          | DEBUG Could not find tap.properties.json in C:\\code\\meltano-windowstest2\\.meltano\\extractors\\tap-csv\\tap.properties.json, skipping.\nmeltano          | DEBUG Could not find tap.properties.cache_key in C:\\code\\meltano-windowstest2\\.meltano\\extractors\\tap-csv\\tap.properties.cache_key, skipping.\nmeltano          | DEBUG Could not find state.json in C:\\code\\meltano-windowstest2\\.meltano\\extractors\\tap-csv\\state.json, skipping.\nmeltano          | DEBUG Variable '$MELTANO_LOAD_SCHEMA' is missing from the environment.\nmeltano          | DEBUG Variable '$MELTANO_LOAD_SCHEMA' is missing from the environment.\nmeltano          | DEBUG Created configuration at C:\\code\\meltano-windowstest2\\.meltano\\run\\elt\\2021-05-05T181221--tap-csv--target-csv\\1aec1d92-7fb9-4e86-885f-f71ddf7f6db1\\target.config.json\nmeltano          | WARNING No state was found, complete import.\nmeltano          | DEBUG Invoking: ['C:\\\\code\\\\meltano-windowstest2\\\\.meltano\\\\extractors\\\\tap-csv\\\\venv\\\\Scripts\\\\tap-csv', '--config', 'C:\\\\code\\\\meltano-windowstest2\\\\.meltano\\\\run\\\\elt\\\\2021-05-05T181221--tap-csv--target-csv\\\\1aec1d92-7fb9-4e86-885f-f71ddf7f6db1\\\\tap.config.json', '--discover']\nmeltano          | DEBUG Env: REDACTED\nmeltano          | WARNING A catalog file was found, but it will be ignored as the extractor does not advertise the `catalog` or `properties` capability\nmeltano          | DEBUG Invoking: ['C:\\\\code\\\\meltano-windowstest2\\\\.meltano\\\\extractors\\\\tap-csv\\\\venv\\\\Scripts\\\\tap-csv', '--config', 'C:\\\\code\\\\meltano-windowstest2\\\\.meltano\\\\run\\\\elt\\\\2021-05-05T181221--tap-csv--target-csv\\\\1aec1d92-7fb9-4e86-885f-f71ddf7f6db1\\\\tap.config.json']\nmeltano          | DEBUG Env: REDACTED\nmeltano          | DEBUG execute program 'C:\\\\code\\\\meltano-windowstest2\\\\.meltano\\\\extractors\\\\tap-csv\\\\venv\\\\Scripts\\\\tap-csv' stdout=<pipe> stderr=<pipe>\nmeltano          | DEBUG process 'C:\\\\code\\\\meltano-windowstest2\\\\.meltano\\\\extractors\\\\tap-csv\\\\venv\\\\Scripts\\\\tap-csv' created: pid 7140\nmeltano          | WARNING Executing <Task pending name='Task-1' coro=<_run_job() running at c:\\users\\derek\\appdata\\local\\programs\\python\\python38\\lib\\site-packages\\meltano\\cli\\elt.py:214> wait_for=<Future pending cb=[<TaskWakeupMethWrapper object at 0x000001A9533305E0>()] created at c:\\users\\derek\\appdata\\local\\programs\\python\\python38\\lib\\asyncio\\base_events.py:422> cb=[_run_until_complete_cb() at c:\\users\\derek\\appdata\\local\\programs\\python\\python38\\lib\\asyncio\\base_events.py:184] created at c:\\users\\derek\\appdata\\local\\programs\\python\\python38\\lib\\site-packages\\meltano\\core\\utils\\__init__.py:37> took 0.969 seconds\nmeltano          | DEBUG <_ProactorReadPipeTransport fd=4>: Fatal read error on pipe transport\nTraceback (most recent call last):\n  File \"c:\\users\\derek\\appdata\\local\\programs\\python\\python38\\lib\\asyncio\\proactor_events.py\", line 299, in _loop_reading\n    self._read_fut = self._loop._proactor.recv(self._sock, 32768)\n  File \"c:\\users\\derek\\appdata\\local\\programs\\python\\python38\\lib\\asyncio\\windows_events.py\", line 445, in recv\n    self._register_with_iocp(conn)\n  File \"c:\\users\\derek\\appdata\\local\\programs\\python\\python38\\lib\\asyncio\\windows_events.py\", line 718, in _register_with_iocp\n    _overlapped.CreateIoCompletionPort(obj.fileno(), self._iocp, 0, 0)\nOSError: [WinError 87] The parameter is incorrect\nmeltano          | ERROR Exception in callback _ProactorReadPipeTransport._loop_reading()\nhandle: <Handle _ProactorReadPipeTransport._loop_reading() created at c:\\users\\derek\\appdata\\local\\programs\\python\\python38\\lib\\asyncio\\proactor_events.py:187>\nsource_traceback: Object created at (most recent call last):\n  File \"c:\\users\\derek\\appdata\\local\\programs\\python\\python38\\lib\\asyncio\\windows_events.py\", line 316, in run_forever\n    super().run_forever()\n  File \"c:\\users\\derek\\appdata\\local\\programs\\python\\python38\\lib\\asyncio\\base_events.py\", line 570, in run_forever\n    self._run_once()\n  File \"c:\\users\\derek\\appdata\\local\\programs\\python\\python38\\lib\\asyncio\\base_events.py\", line 1851, in _run_once\n    handle._run()\n  File \"c:\\users\\derek\\appdata\\local\\programs\\python\\python38\\lib\\asyncio\\events.py\", line 81, in _run\n    self._context.run(self._callback, *self._args)\n  File \"c:\\users\\derek\\appdata\\local\\programs\\python\\python38\\lib\\site-packages\\meltano\\core\\logging\\output_logger.py\", line 201, in _read_from_fd\n    read_transport, _ = await loop.connect_read_pipe(\n  File \"c:\\users\\derek\\appdata\\local\\programs\\python\\python38\\lib\\asyncio\\base_events.py\", line 1525, in connect_read_pipe\n    transport = self._make_read_pipe_transport(pipe, protocol, waiter)\n  File \"c:\\users\\derek\\appdata\\local\\programs\\python\\python38\\lib\\asyncio\\proactor_events.py\", line 664, in _make_read_pipe_transport\n    return _ProactorReadPipeTransport(self, sock, protocol, waiter, extra)\n  File \"c:\\users\\derek\\appdata\\local\\programs\\python\\python38\\lib\\asyncio\\proactor_events.py\", line 187, in __init__\n    self._loop.call_soon(self._loop_reading)\nTraceback (most recent call last):\n  File \"c:\\users\\derek\\appdata\\local\\programs\\python\\python38\\lib\\asyncio\\proactor_events.py\", line 299, in _loop_reading\n    self._read_fut = self._loop._proactor.recv(self._sock, 32768)\n  File \"c:\\users\\derek\\appdata\\local\\programs\\python\\python38\\lib\\asyncio\\windows_events.py\", line 445, in recv\n    self._register_with_iocp(conn)\n  File \"c:\\users\\derek\\appdata\\local\\programs\\python\\python38\\lib\\asyncio\\windows_events.py\", line 718, in _register_with_iocp\n    _overlapped.CreateIoCompletionPort(obj.fileno(), self._iocp, 0, 0)\nOSError: [WinError 87] The parameter is incorrect\n\nDuring handling of the above exception, another exception occurred:\n\nTraceback (most recent call last):\n  File \"c:\\users\\derek\\appdata\\local\\programs\\python\\python38\\lib\\asyncio\\events.py\", line 81, in _run\n    self._context.run(self._callback, *self._args)\n  File \"c:\\users\\derek\\appdata\\local\\programs\\python\\python38\\lib\\asyncio\\proactor_events.py\", line 309, in _loop_reading\n    self._fatal_error(exc, 'Fatal read error on pipe transport')\n  File \"c:\\users\\derek\\appdata\\local\\programs\\python\\python38\\lib\\asyncio\\proactor_events.py\", line 131, in _fatal_error\n    self._force_close(exc)\n  File \"c:\\users\\derek\\appdata\\local\\programs\\python\\python38\\lib\\asyncio\\proactor_events.py\", line 134, in _force_close\n    if self._empty_waiter is not None and not self._empty_waiter.done():\nAttributeError: '_ProactorReadPipeTransport' object has no attribute '_empty_waiter'\nmeltano          | DEBUG <_ProactorReadPipeTransport fd=6>: Fatal read error on pipe transport\nTraceback (most recent call last):\n  File \"c:\\users\\derek\\appdata\\local\\programs\\python\\python38\\lib\\asyncio\\proactor_events.py\", line 299, in _loop_reading\n    self._read_fut = self._loop._proactor.recv(self._sock, 32768)\n  File \"c:\\users\\derek\\appdata\\local\\programs\\python\\python38\\lib\\asyncio\\windows_events.py\", line 445, in recv\n    self._register_with_iocp(conn)\n  File \"c:\\users\\derek\\appdata\\local\\programs\\python\\python38\\lib\\asyncio\\windows_events.py\", line 718, in _register_with_iocp\n    _overlapped.CreateIoCompletionPort(obj.fileno(), self._iocp, 0, 0)\nOSError: [WinError 87] The parameter is incorrect\nmeltano          | ERROR Exception in callback _ProactorReadPipeTransport._loop_reading()\nhandle: <Handle _ProactorReadPipeTransport._loop_reading() created at c:\\users\\derek\\appdata\\local\\programs\\python\\python38\\lib\\asyncio\\proactor_events.py:187>\nsource_traceback: Object created at (most recent call last):\n  File \"c:\\users\\derek\\appdata\\local\\programs\\python\\python38\\lib\\asyncio\\windows_events.py\", line 316, in run_forever\n    super().run_forever()\n  File \"c:\\users\\derek\\appdata\\local\\programs\\python\\python38\\lib\\asyncio\\base_events.py\", line 570, in run_forever\n    self._run_once()\n  File \"c:\\users\\derek\\appdata\\local\\programs\\python\\python38\\lib\\asyncio\\base_events.py\", line 1851, in _run_once\n    handle._run()\n  File \"c:\\users\\derek\\appdata\\local\\programs\\python\\python38\\lib\\asyncio\\events.py\", line 81, in _run\n    self._context.run(self._callback, *self._args)\n  File \"c:\\users\\derek\\appdata\\local\\programs\\python\\python38\\lib\\site-packages\\meltano\\core\\logging\\output_logger.py\", line 201, in _read_from_fd\n    read_transport, _ = await loop.connect_read_pipe(\n  File \"c:\\users\\derek\\appdata\\local\\programs\\python\\python38\\lib\\asyncio\\base_events.py\", line 1525, in connect_read_pipe\n    transport = self._make_read_pipe_transport(pipe, protocol, waiter)\n  File \"c:\\users\\derek\\appdata\\local\\programs\\python\\python38\\lib\\asyncio\\proactor_events.py\", line 664, in _make_read_pipe_transport\n    return _ProactorReadPipeTransport(self, sock, protocol, waiter, extra)\n  File \"c:\\users\\derek\\appdata\\local\\programs\\python\\python38\\lib\\asyncio\\proactor_events.py\", line 187, in __init__\n    self._loop.call_soon(self._loop_reading)\nTraceback (most recent call last):\n  File \"c:\\users\\derek\\appdata\\local\\programs\\python\\python38\\lib\\asyncio\\proactor_events.py\", line 299, in _loop_reading\n    self._read_fut = self._loop._proactor.recv(self._sock, 32768)\n  File \"c:\\users\\derek\\appdata\\local\\programs\\python\\python38\\lib\\asyncio\\windows_events.py\", line 445, in recv\n    self._register_with_iocp(conn)\n  File \"c:\\users\\derek\\appdata\\local\\programs\\python\\python38\\lib\\asyncio\\windows_events.py\", line 718, in _register_with_iocp\n    _overlapped.CreateIoCompletionPort(obj.fileno(), self._iocp, 0, 0)\nOSError: [WinError 87] The parameter is incorrect\n\nDuring handling of the above exception, another exception occurred:\n\nTraceback (most recent call last):\n  File \"c:\\users\\derek\\appdata\\local\\programs\\python\\python38\\lib\\asyncio\\events.py\", line 81, in _run\n    self._context.run(self._callback, *self._args)\n  File \"c:\\users\\derek\\appdata\\local\\programs\\python\\python38\\lib\\asyncio\\proactor_events.py\", line 309, in _loop_reading\n    self._fatal_error(exc, 'Fatal read error on pipe transport')\n  File \"c:\\users\\derek\\appdata\\local\\programs\\python\\python38\\lib\\asyncio\\proactor_events.py\", line 131, in _fatal_error\n    self._force_close(exc)\n  File \"c:\\users\\derek\\appdata\\local\\programs\\python\\python38\\lib\\asyncio\\proactor_events.py\", line 134, in _force_close\n    if self._empty_waiter is not None and not self._empty_waiter.done():\nAttributeError: '_ProactorReadPipeTransport' object has no attribute '_empty_waiter'\nmeltano          | DEBUG Read pipe 4 connected: (<_ProactorReadPipeTransport fd=4>, <asyncio.streams.StreamReaderProtocol object at 0x000001A9530B7B20>)\nmeltano          | DEBUG Read pipe 6 connected: (<_ProactorReadPipeTransport fd=6>, <asyncio.streams.StreamReaderProtocol object at 0x000001A9530B7CD0>)\nmeltano          | DEBUG Read pipe 836 connected: (<_ProactorReadPipeTransport fd=836 read=<_OverlappedFuture pending overlapped=<pending, 0x1a953203dc0> cb=[_ProactorReadPipeTransport._loop_reading()] created at c:\\users\\derek\\appdata\\local\\programs\\python\\python38\\lib\\asyncio\\windows_events.py:465>>, <ReadSubprocessPipeProto fd=1 pipe=<_ProactorReadPipeTransport fd=836 read=<_OverlappedFuture pending overlapped=<pending, 0x1a953203dc0> cb=[_ProactorReadPipeTransport._loop_reading()] created at c:\\users\\derek\\appdata\\local\\programs\\python\\python38\\lib\\asyncio\\windows_events.py:465>>>)\nmeltano          | DEBUG Read pipe 876 connected: (<_ProactorReadPipeTransport fd=876 read=<_OverlappedFuture pending overlapped=<pending, 0x1a9531180d0> cb=[_ProactorReadPipeTransport._loop_reading()] created at c:\\users\\derek\\appdata\\local\\programs\\python\\python38\\lib\\asyncio\\windows_events.py:465>>, <ReadSubprocessPipeProto fd=2 pipe=<_ProactorReadPipeTransport fd=876 read=<_OverlappedFuture pending overlapped=<pending, 0x1a9531180d0> cb=[_ProactorReadPipeTransport._loop_reading()] created at c:\\users\\derek\\appdata\\local\\programs\\python\\python38\\lib\\asyncio\\windows_events.py:465>>>)\nmeltano          | INFO execute program 'C:\\\\code\\\\meltano-windowstest2\\\\.meltano\\\\extractors\\\\tap-csv\\\\venv\\\\Scripts\\\\tap-csv': <_WindowsSubprocessTransport pid=7140 running stdout=<_ProactorReadPipeTransport fd=836 read=<_OverlappedFuture pending overlapped=<pending, 0x1a953203dc0> cb=[_ProactorReadPipeTransport._loop_reading()] created at c:\\users\\derek\\appdata\\local\\programs\\python\\python38\\lib\\asyncio\\windows_events.py:465>> stderr=<_ProactorReadPipeTransport fd=876 read=<_OverlappedFuture pending overlapped=<pending, 0x1a9531180d0> cb=[_ProactorReadPipeTransport._loop_reading()] created at c:\\users\\derek\\appdata\\local\\programs\\python\\python38\\lib\\asyncio\\windows_events.py:465>>>\nmeltano          | DEBUG Invoking: ['C:\\\\code\\\\meltano-windowstest2\\\\.meltano\\\\loaders\\\\target-csv\\\\venv\\\\Scripts\\\\target-csv', '--config', 'C:\\\\code\\\\meltano-windowstest2\\\\.meltano\\\\run\\\\elt\\\\2021-05-05T181221--tap-csv--target-csv\\\\1aec1d92-7fb9-4e86-885f-f71ddf7f6db1\\\\target.config.json']\nmeltano          | DEBUG Env: REDACTED\nmeltano          | DEBUG execute program 'C:\\\\code\\\\meltano-windowstest2\\\\.meltano\\\\loaders\\\\target-csv\\\\venv\\\\Scripts\\\\target-csv' stdin=<pipe> stdout=<pipe> stderr=<pipe>\nmeltano          | DEBUG process 'C:\\\\code\\\\meltano-windowstest2\\\\.meltano\\\\loaders\\\\target-csv\\\\venv\\\\Scripts\\\\target-csv' created: pid 18608\nmeltano          | DEBUG Write pipe 904 connected: (<_ProactorWritePipeTransport fd=904 read=<_OverlappedFuture pending overlapped=<pending, 0x1a953375430> cb=[_ProactorWritePipeTransport._pipe_closed()] created at c:\\users\\derek\\appdata\\local\\programs\\python\\python38\\lib\\asyncio\\windows_events.py:465>>, <WriteSubprocessPipeProto fd=0 pipe=<_ProactorWritePipeTransport fd=904 read=<_OverlappedFuture pending overlapped=<pending, 0x1a953375430> cb=[_ProactorWritePipeTransport._pipe_closed()] created at c:\\users\\derek\\appdata\\local\\programs\\python\\python38\\lib\\asyncio\\windows_events.py:465>>>)\nmeltano          | DEBUG Read pipe 968 connected: (<_ProactorReadPipeTransport fd=968 read=<_OverlappedFuture pending overlapped=<pending, 0x1a953375550> cb=[_ProactorReadPipeTransport._loop_reading()] created at c:\\users\\derek\\appdata\\local\\programs\\python\\python38\\lib\\asyncio\\windows_events.py:465>>, <ReadSubprocessPipeProto fd=1 pipe=<_ProactorReadPipeTransport fd=968 read=<_OverlappedFuture pending overlapped=<pending, 0x1a953375550> cb=[_ProactorReadPipeTransport._loop_reading()] created at c:\\users\\derek\\appdata\\local\\programs\\python\\python38\\lib\\asyncio\\windows_events.py:465>>>)\nmeltano          | DEBUG Read pipe 920 connected: (<_ProactorReadPipeTransport fd=920 read=<_OverlappedFuture pending overlapped=<pending, 0x1a953375670> cb=[_ProactorReadPipeTransport._loop_reading()] created at c:\\users\\derek\\appdata\\local\\programs\\python\\python38\\lib\\asyncio\\windows_events.py:465>>, <ReadSubprocessPipeProto fd=2 pipe=<_ProactorReadPipeTransport fd=920 read=<_OverlappedFuture pending overlapped=<pending, 0x1a953375670> cb=[_ProactorReadPipeTransport._loop_reading()] created at c:\\users\\derek\\appdata\\local\\programs\\python\\python38\\lib\\asyncio\\windows_events.py:465>>>)\nmeltano          | INFO execute program 'C:\\\\code\\\\meltano-windowstest2\\\\.meltano\\\\loaders\\\\target-csv\\\\venv\\\\Scripts\\\\target-csv': <_WindowsSubprocessTransport pid=18608 running stdin=<_ProactorWritePipeTransport fd=904 read=<_OverlappedFuture pending overlapped=<pending, 0x1a953375430> cb=[_ProactorWritePipeTransport._pipe_closed()] created at c:\\users\\derek\\appdata\\local\\programs\\python\\python38\\lib\\asyncio\\windows_events.py:465>> stdout=<_ProactorReadPipeTransport fd=968 read=<_OverlappedFuture pending overlapped=<pending, 0x1a953375550> cb=[_ProactorReadPipeTransport._loop_reading()] created at c:\\users\\derek\\appdata\\local\\programs\\python\\python38\\lib\\asyncio\\windows_events.py:465>> stderr=<_ProactorReadPipeTransport fd=920 read=<_OverlappedFuture pending overlapped=<pending, 0x1a953375670> cb=[_ProactorReadPipeTransport._loop_reading()] created at c:\\users\\derek\\appdata\\local\\programs\\python\\python38\\lib\\asyncio\\windows_events.py:465>>>\ntap-csv          | INFO Starting sync\ntap-csv          | INFO Syncing entity 'things' from file: 'input.csv'\ntap-csv (out)    | {\"type\": \"SCHEMA\", \"stream\": \"things\", \"schema\": {\"type\": \"object\", \"properties\": {\"id\": {\"type\": \"string\"}, \" name\": {\"type\": \"string\"}}}, \"key_properties\": [\"id\"]}\ntap-csv (out)    | {\"type\": \"RECORD\", \"stream\": \"things\", \"record\": {\"id\": \"1\", \" name\": \" Derek\"}}\ntap-csv (out)    | {\"type\": \"RECORD\", \"stream\": \"things\", \"record\": {\"id\": \"2\", \" name\": \" Cener\"}}\ntap-csv (out)    | {\"type\": \"STATE\", \"value\": {}}\ntap-csv          | INFO Sync completed\nmeltano          | DEBUG <_ProactorReadPipeTransport fd=876> received EOF\nmeltano          | DEBUG <_ProactorReadPipeTransport fd=836> received EOF\nmeltano          | INFO <_WindowsSubprocessTransport pid=7140 running stdout=<_ProactorReadPipeTransport closing fd=836> stderr=<_ProactorReadPipeTransport closing fd=876>> exited with return code 0\ntarget-csv       | INFO Sending version information to singer.io. To disable sending anonymous usage data, set the config parameter \"disable_collection\" to true\ntarget-csv (out) | {}\nmeltano          | INFO Incremental state has been updated at 2021-05-05 18:12:22.353325.\nmeltano          | DEBUG Incremental state: {}\nmeltano          | DEBUG <_ProactorReadPipeTransport fd=968> received EOF\nmeltano          | DEBUG <_ProactorReadPipeTransport fd=920> received EOF\nmeltano          | INFO <_WindowsSubprocessTransport pid=18608 running stdin=<_ProactorWritePipeTransport closed> stdout=<_ProactorReadPipeTransport closing fd=968> stderr=<_ProactorReadPipeTransport closing fd=920>> exited with return code 0\nmeltano          | DEBUG Deleted configuration at C:\\code\\meltano-windowstest2\\.meltano\\run\\elt\\2021-05-05T181221--tap-csv--target-csv\\1aec1d92-7fb9-4e86-885f-f71ddf7f6db1\\target.config.json\nmeltano          | DEBUG Deleted configuration at C:\\code\\meltano-windowstest2\\.meltano\\run\\elt\\2021-05-05T181221--tap-csv--target-csv\\1aec1d92-7fb9-4e86-885f-f71ddf7f6db1\\tap.config.json\nmeltano          | INFO Extract & load complete!\nmeltano          | INFO Transformation skipped.\n\nAborted!\nException ignored in: <coroutine object _run_job at 0x000001A9530120C0>\nRuntimeError: coroutine ignored GeneratorExit\nmeltano          | ERROR Task was destroyed but it is pending!\nsource_traceback: Object created at (most recent call last):\n  File \"c:\\users\\derek\\appdata\\local\\programs\\python\\python38\\lib\\runpy.py\", line 194, in _run_module_as_main\n    return _run_code(code, main_globals, None,\n  File \"c:\\users\\derek\\appdata\\local\\programs\\python\\python38\\lib\\runpy.py\", line 87, in _run_code\n    exec(code, run_globals)\n  File \"C:\\Users\\derek\\AppData\\Local\\Programs\\Python\\Python38\\Scripts\\meltano.exe\\__main__.py\", line 7, in <module>\n    sys.exit(main())\n  File \"c:\\users\\derek\\appdata\\local\\programs\\python\\python38\\lib\\site-packages\\meltano\\cli\\__init__.py\", line 43, in main\n    cli(obj={\"project\": None})\n  File \"c:\\users\\derek\\appdata\\local\\programs\\python\\python38\\lib\\site-packages\\click\\core.py\", line 829, in __call__\n    return self.main(*args, **kwargs)\n  File \"c:\\users\\derek\\appdata\\local\\programs\\python\\python38\\lib\\site-packages\\click\\core.py\", line 782, in main\n    rv = self.invoke(ctx)\n  File \"c:\\users\\derek\\appdata\\local\\programs\\python\\python38\\lib\\site-packages\\click\\core.py\", line 1259, in invoke\n    return _process_result(sub_ctx.command.invoke(sub_ctx))\n  File \"c:\\users\\derek\\appdata\\local\\programs\\python\\python38\\lib\\site-packages\\click\\core.py\", line 1066, in invoke\n    return ctx.invoke(self.callback, **ctx.params)\n  File \"c:\\users\\derek\\appdata\\local\\programs\\python\\python38\\lib\\site-packages\\click\\core.py\", line 610, in invoke\n    return callback(*args, **kwargs)\n  File \"c:\\users\\derek\\appdata\\local\\programs\\python\\python38\\lib\\site-packages\\meltano\\cli\\params.py\", line 23, in decorate\n    return func(*args, **kwargs)\n  File \"c:\\users\\derek\\appdata\\local\\programs\\python\\python38\\lib\\site-packages\\meltano\\cli\\params.py\", line 57, in decorate\n    func(project, *args, **kwargs)\n  File \"c:\\users\\derek\\appdata\\local\\programs\\python\\python38\\lib\\site-packages\\meltano\\cli\\elt.py\", line 137, in elt\n    run_async(_run_job(project, job, session, context_builder, force=force))\n  File \"c:\\users\\derek\\appdata\\local\\programs\\python\\python38\\lib\\site-packages\\meltano\\core\\utils\\__init__.py\", line 37, in run_async\n    future = asyncio.ensure_future(coro)\ntask: <Task pending name='Task-1' coro=<_run_job() running at c:\\users\\derek\\appdata\\local\\programs\\python\\python38\\lib\\site-packages\\meltano\\cli\\elt.py:214> wait_for=<Task pending name='Task-4' coro=<Out._read_from_fd() running at c:\\users\\derek\\appdata\\local\\programs\\python\\python38\\lib\\site-packages\\meltano\\core\\logging\\output_logger.py:205> wait_for=<Future pending cb=[<TaskWakeupMethWrapper object at 0x000001A9530B7CA0>()] created at c:\\users\\derek\\appdata\\local\\programs\\python\\python38\\lib\\asyncio\\base_events.py:422> cb=[<TaskWakeupMethWrapper object at 0x000001A953330040>()] created at c:\\users\\derek\\appdata\\local\\programs\\python\\python38\\lib\\site-packages\\meltano\\core\\logging\\output_logger.py:148> created at c:\\users\\derek\\appdata\\local\\programs\\python\\python38\\lib\\site-packages\\meltano\\core\\utils\\__init__.py:37>\n--- Logging error ---\nTraceback (most recent call last):\n  File \"c:\\users\\derek\\appdata\\local\\programs\\python\\python38\\lib\\logging\\__init__.py\", line 1084, in emit\n    stream.write(msg + self.terminator)\n  File \"c:\\users\\derek\\appdata\\local\\programs\\python\\python38\\lib\\site-packages\\meltano\\core\\logging\\output_logger.py\", line 65, in write\n    self.__out.writeline(line)\n  File \"c:\\users\\derek\\appdata\\local\\programs\\python\\python38\\lib\\site-packages\\meltano\\core\\logging\\output_logger.py\", line 174, in writeline\n    click.echo(self.prefix + line, nl=False, file=self)\n  File \"c:\\users\\derek\\appdata\\local\\programs\\python\\python38\\lib\\site-packages\\click\\utils.py\", line 272, in echo\n    file.write(message)\n  File \"c:\\users\\derek\\appdata\\local\\programs\\python\\python38\\lib\\site-packages\\click\\_compat.py\", line 710, in _safe_write\n    return _write(s)\n  File \"c:\\users\\derek\\appdata\\local\\programs\\python\\python38\\lib\\site-packages\\colorama\\ansitowin32.py\", line 41, in write\n    self.__convertor.write(text)\n  File \"c:\\users\\derek\\appdata\\local\\programs\\python\\python38\\lib\\site-packages\\colorama\\ansitowin32.py\", line 164, in write\n    self.wrapped.write(text)\n  File \"c:\\users\\derek\\appdata\\local\\programs\\python\\python38\\lib\\site-packages\\meltano\\core\\logging\\output_logger.py\", line 179, in write\n    self.file.write(remove_ansi_escape_sequences(data))\nValueError: I/O operation on closed file.\nCall stack:\n  File \"c:\\users\\derek\\appdata\\local\\programs\\python\\python38\\lib\\asyncio\\base_events.py\", line 1733, in call_exception_handler\n    self.default_exception_handler(context)\n  File \"c:\\users\\derek\\appdata\\local\\programs\\python\\python38\\lib\\asyncio\\base_events.py\", line 1707, in default_exception_handler\n    logger.error('\\n'.join(log_lines), exc_info=exc_info)\nMessage: 'Task was destroyed but it is pending!\\nsource_traceback: Object created at (most recent call last):\\n  File \"c:\\\\users\\\\derek\\\\appdata\\\\local\\\\programs\\\\python\\\\python38\\\\lib\\\\runpy.py\", line 194, in _run_module_as_main\\n    return _run_code(code, main_globals, None,\\n  File \"c:\\\\users\\\\derek\\\\appdata\\\\local\\\\programs\\\\python\\\\python38\\\\lib\\\\runpy.py\", line 87, in _run_code\\n    exec(code, run_globals)\\n  File \"C:\\\\Users\\\\derek\\\\AppData\\\\Local\\\\Programs\\\\Python\\\\Python38\\\\Scripts\\\\meltano.exe\\\\__main__.py\", line 7, in <module>\\n    sys.exit(main())\\n  File \"c:\\\\users\\\\derek\\\\appdata\\\\local\\\\programs\\\\python\\\\python38\\\\lib\\\\site-packages\\\\meltano\\\\cli\\\\__init__.py\", line 43, in main\\n    cli(obj={\"project\": None})\\n  File \"c:\\\\users\\\\derek\\\\appdata\\\\local\\\\programs\\\\python\\\\python38\\\\lib\\\\site-packages\\\\click\\\\core.py\", line 829, in __call__\\n    return self.main(*args, **kwargs)\\n  File \"c:\\\\users\\\\derek\\\\appdata\\\\local\\\\programs\\\\python\\\\python38\\\\lib\\\\site-packages\\\\click\\\\core.py\", line 782, in main\\n    rv = self.invoke(ctx)\\n  File \"c:\\\\users\\\\derek\\\\appdata\\\\local\\\\programs\\\\python\\\\python38\\\\lib\\\\site-packages\\\\click\\\\core.py\", line 1259, in invoke\\n    return _process_result(sub_ctx.command.invoke(sub_ctx))\\n  File \"c:\\\\users\\\\derek\\\\appdata\\\\local\\\\programs\\\\python\\\\python38\\\\lib\\\\site-packages\\\\click\\\\core.py\", line 1066, in invoke\\n    return ctx.invoke(self.callback, **ctx.params)\\n  File \"c:\\\\users\\\\derek\\\\appdata\\\\local\\\\programs\\\\python\\\\python38\\\\lib\\\\site-packages\\\\click\\\\core.py\", line 610, in invoke\\n    return callback(*args, **kwargs)\\n  File \"c:\\\\users\\\\derek\\\\appdata\\\\local\\\\programs\\\\python\\\\python38\\\\lib\\\\site-packages\\\\meltano\\\\cli\\\\params.py\", line 23, in decorate\\n    return func(*args, **kwargs)\\n  File \"c:\\\\users\\\\derek\\\\appdata\\\\local\\\\programs\\\\python\\\\python38\\\\lib\\\\site-packages\\\\meltano\\\\cli\\\\params.py\", line 57, in decorate\\n    func(project, *args, **kwargs)\\n  File \"c:\\\\users\\\\derek\\\\appdata\\\\local\\\\programs\\\\python\\\\python38\\\\lib\\\\site-packages\\\\meltano\\\\cli\\\\elt.py\", line 137, in elt\\n    run_async(_run_job(project, job, session, context_builder, force=force))\\n  File \"c:\\\\users\\\\derek\\\\appdata\\\\local\\\\programs\\\\python\\\\python38\\\\lib\\\\site-packages\\\\meltano\\\\core\\\\utils\\\\__init__.py\", line 37, in run_async\\n    future = asyncio.ensure_future(coro)\\ntask: <Task pending name=\\'Task-1\\' coro=<_run_job() running at c:\\\\users\\\\derek\\\\appdata\\\\local\\\\programs\\\\python\\\\python38\\\\lib\\\\site-packages\\\\meltano\\\\cli\\\\elt.py:214> wait_for=<Task pending name=\\'Task-4\\' coro=<Out._read_from_fd() running at c:\\\\users\\\\derek\\\\appdata\\\\local\\\\programs\\\\python\\\\python38\\\\lib\\\\site-packages\\\\meltano\\\\core\\\\logging\\\\output_logger.py:205> wait_for=<Future pending cb=[<TaskWakeupMethWrapper object at 0x000001A9530B7CA0>()] created at c:\\\\users\\\\derek\\\\appdata\\\\local\\\\programs\\\\python\\\\python38\\\\lib\\\\asyncio\\\\base_events.py:422> cb=[<TaskWakeupMethWrapper object at 0x000001A953330040>()] created at c:\\\\users\\\\derek\\\\appdata\\\\local\\\\programs\\\\python\\\\python38\\\\lib\\\\site-packages\\\\meltano\\\\core\\\\logging\\\\output_logger.py:148> created at c:\\\\users\\\\derek\\\\appdata\\\\local\\\\programs\\\\python\\\\python38\\\\lib\\\\site-packages\\\\meltano\\\\core\\\\utils\\\\__init__.py:37>'\nArguments: ()\nException ignored in: <generator object Job._handling_sigterm at 0x000001A953096AC0>\nTraceback (most recent call last):\n  File \"c:\\users\\derek\\appdata\\local\\programs\\python\\python38\\lib\\site-packages\\meltano\\core\\job\\job.py\", line 229, in _handling_sigterm\n    signal.signal(signal.SIGTERM, original_termination_handler)\n  File \"c:\\users\\derek\\appdata\\local\\programs\\python\\python38\\lib\\signal.py\", line 47, in signal\n    handler = _signal.signal(_enum_to_int(signalnum), _enum_to_int(handler))\nTypeError: signal handler must be signal.SIG_IGN, signal.SIG_DFL, or a callable object\nmeltano          | ERROR Task was destroyed but it is pending!\nsource_traceback: Object created at (most recent call last):\n  File \"c:\\users\\derek\\appdata\\local\\programs\\python\\python38\\lib\\runpy.py\", line 194, in _run_module_as_main\n    return _run_code(code, main_globals, None,\n  File \"c:\\users\\derek\\appdata\\local\\programs\\python\\python38\\lib\\runpy.py\", line 87, in _run_code\n    exec(code, run_globals)\n  File \"C:\\Users\\derek\\AppData\\Local\\Programs\\Python\\Python38\\Scripts\\meltano.exe\\__main__.py\", line 7, in <module>\n    sys.exit(main())\n  File \"c:\\users\\derek\\appdata\\local\\programs\\python\\python38\\lib\\site-packages\\meltano\\cli\\__init__.py\", line 43, in main\n    cli(obj={\"project\": None})\n  File \"c:\\users\\derek\\appdata\\local\\programs\\python\\python38\\lib\\site-packages\\click\\core.py\", line 829, in __call__\n    return self.main(*args, **kwargs)\n  File \"c:\\users\\derek\\appdata\\local\\programs\\python\\python38\\lib\\site-packages\\click\\core.py\", line 782, in main\n    rv = self.invoke(ctx)\n  File \"c:\\users\\derek\\appdata\\local\\programs\\python\\python38\\lib\\site-packages\\click\\core.py\", line 1259, in invoke\n    return _process_result(sub_ctx.command.invoke(sub_ctx))\n  File \"c:\\users\\derek\\appdata\\local\\programs\\python\\python38\\lib\\site-packages\\click\\core.py\", line 1066, in invoke\n    return ctx.invoke(self.callback, **ctx.params)\n  File \"c:\\users\\derek\\appdata\\local\\programs\\python\\python38\\lib\\site-packages\\click\\core.py\", line 610, in invoke\n    return callback(*args, **kwargs)\n  File \"c:\\users\\derek\\appdata\\local\\programs\\python\\python38\\lib\\site-packages\\meltano\\cli\\params.py\", line 23, in decorate\n    return func(*args, **kwargs)\n  File \"c:\\users\\derek\\appdata\\local\\programs\\python\\python38\\lib\\site-packages\\meltano\\cli\\params.py\", line 57, in decorate\n    func(project, *args, **kwargs)\n  File \"c:\\users\\derek\\appdata\\local\\programs\\python\\python38\\lib\\site-packages\\meltano\\cli\\elt.py\", line 137, in elt\n    run_async(_run_job(project, job, session, context_builder, force=force))\n  File \"c:\\users\\derek\\appdata\\local\\programs\\python\\python38\\lib\\site-packages\\meltano\\core\\utils\\__init__.py\", line 39, in run_async\n    loop.run_until_complete(future)\n  File \"c:\\users\\derek\\appdata\\local\\programs\\python\\python38\\lib\\asyncio\\base_events.py\", line 603, in run_until_complete\n    self.run_forever()\n  File \"c:\\users\\derek\\appdata\\local\\programs\\python\\python38\\lib\\asyncio\\windows_events.py\", line 316, in run_forever\n    super().run_forever()\n  File \"c:\\users\\derek\\appdata\\local\\programs\\python\\python38\\lib\\asyncio\\base_events.py\", line 570, in run_forever\n    self._run_once()\n  File \"c:\\users\\derek\\appdata\\local\\programs\\python\\python38\\lib\\asyncio\\base_events.py\", line 1851, in _run_once\n    handle._run()\n  File \"c:\\users\\derek\\appdata\\local\\programs\\python\\python38\\lib\\asyncio\\events.py\", line 81, in _run\n    self._context.run(self._callback, *self._args)\n  File \"c:\\users\\derek\\appdata\\local\\programs\\python\\python38\\lib\\site-packages\\meltano\\cli\\elt.py\", line 214, in _run_job\n    await _run_elt(project, context_builder, output_logger)\n  File \"c:\\users\\derek\\appdata\\local\\programs\\python\\python38\\lib\\site-packages\\meltano\\cli\\elt.py\", line 232, in _run_elt\n    async with _redirect_output(output_logger):\n  File \"c:\\users\\derek\\appdata\\local\\programs\\python\\python38\\lib\\site-packages\\async_generator\\_util.py\", line 34, in __aenter__\n    return await self._agen.asend(None)\n  File \"c:\\users\\derek\\appdata\\local\\programs\\python\\python38\\lib\\site-packages\\meltano\\cli\\elt.py\", line 223, in _redirect_output\n    async with meltano_stdout.redirect_stdout(), meltano_stderr.redirect_stderr():\n  File \"c:\\users\\derek\\appdata\\local\\programs\\python\\python38\\lib\\site-packages\\async_generator\\_util.py\", line 34, in __aenter__\n    return await self._agen.asend(None)\n  File \"c:\\users\\derek\\appdata\\local\\programs\\python\\python38\\lib\\site-packages\\meltano\\core\\logging\\output_logger.py\", line 161, in redirect_stdout\n    async with self.writer() as stdout:\n  File \"c:\\users\\derek\\appdata\\local\\programs\\python\\python38\\lib\\site-packages\\async_generator\\_util.py\", line 34, in __aenter__\n    return await self._agen.asend(None)\n  File \"c:\\users\\derek\\appdata\\local\\programs\\python\\python38\\lib\\site-packages\\meltano\\core\\logging\\output_logger.py\", line 148, in writer\n    reader = asyncio.ensure_future(self._read_from_fd(read_fd))\ntask: <Task pending name='Task-3' coro=<Out._read_from_fd() running at c:\\users\\derek\\appdata\\local\\programs\\python\\python38\\lib\\site-packages\\meltano\\core\\logging\\output_logger.py:205> wait_for=<Future pending cb=[<TaskWakeupMethWrapper object at 0x000001A9531164F0>()] created at c:\\users\\derek\\appdata\\local\\programs\\python\\python38\\lib\\asyncio\\base_events.py:422> created at c:\\users\\derek\\appdata\\local\\programs\\python\\python38\\lib\\site-packages\\meltano\\core\\logging\\output_logger.py:148>\n--- Logging error ---\nTraceback (most recent call last):\n  File \"c:\\users\\derek\\appdata\\local\\programs\\python\\python38\\lib\\logging\\__init__.py\", line 1084, in emit\n    stream.write(msg + self.terminator)\n  File \"c:\\users\\derek\\appdata\\local\\programs\\python\\python38\\lib\\site-packages\\meltano\\core\\logging\\output_logger.py\", line 65, in write\n    self.__out.writeline(line)\n  File \"c:\\users\\derek\\appdata\\local\\programs\\python\\python38\\lib\\site-packages\\meltano\\core\\logging\\output_logger.py\", line 174, in writeline\n    click.echo(self.prefix + line, nl=False, file=self)\n  File \"c:\\users\\derek\\appdata\\local\\programs\\python\\python38\\lib\\site-packages\\click\\utils.py\", line 272, in echo\n    file.write(message)\n  File \"c:\\users\\derek\\appdata\\local\\programs\\python\\python38\\lib\\site-packages\\click\\_compat.py\", line 710, in _safe_write\n    return _write(s)\n  File \"c:\\users\\derek\\appdata\\local\\programs\\python\\python38\\lib\\site-packages\\colorama\\ansitowin32.py\", line 41, in write\n    self.__convertor.write(text)\n  File \"c:\\users\\derek\\appdata\\local\\programs\\python\\python38\\lib\\site-packages\\colorama\\ansitowin32.py\", line 164, in write\n    self.wrapped.write(text)\n  File \"c:\\users\\derek\\appdata\\local\\programs\\python\\python38\\lib\\site-packages\\meltano\\core\\logging\\output_logger.py\", line 179, in write\n    self.file.write(remove_ansi_escape_sequences(data))\nValueError: I/O operation on closed file.\nCall stack:\n  File \"c:\\users\\derek\\appdata\\local\\programs\\python\\python38\\lib\\asyncio\\base_events.py\", line 1733, in call_exception_handler\n    self.default_exception_handler(context)\n  File \"c:\\users\\derek\\appdata\\local\\programs\\python\\python38\\lib\\asyncio\\base_events.py\", line 1707, in default_exception_handler\n    logger.error('\\n'.join(log_lines), exc_info=exc_info)\nMessage: 'Task was destroyed but it is pending!\\nsource_traceback: Object created at (most recent call last):\\n  File \"c:\\\\users\\\\derek\\\\appdata\\\\local\\\\programs\\\\python\\\\python38\\\\lib\\\\runpy.py\", line 194, in _run_module_as_main\\n    return _run_code(code, main_globals, None,\\n  File \"c:\\\\users\\\\derek\\\\appdata\\\\local\\\\programs\\\\python\\\\python38\\\\lib\\\\runpy.py\", line 87, in _run_code\\n    exec(code, run_globals)\\n  File \"C:\\\\Users\\\\derek\\\\AppData\\\\Local\\\\Programs\\\\Python\\\\Python38\\\\Scripts\\\\meltano.exe\\\\__main__.py\", line 7, in <module>\\n    sys.exit(main())\\n  File \"c:\\\\users\\\\derek\\\\appdata\\\\local\\\\programs\\\\python\\\\python38\\\\lib\\\\site-packages\\\\meltano\\\\cli\\\\__init__.py\", line 43, in main\\n    cli(obj={\"project\": None})\\n  File \"c:\\\\users\\\\derek\\\\appdata\\\\local\\\\programs\\\\python\\\\python38\\\\lib\\\\site-packages\\\\click\\\\core.py\", line 829, in __call__\\n    return self.main(*args, **kwargs)\\n  File \"c:\\\\users\\\\derek\\\\appdata\\\\local\\\\programs\\\\python\\\\python38\\\\lib\\\\site-packages\\\\click\\\\core.py\", line 782, in main\\n    rv = self.invoke(ctx)\\n  File \"c:\\\\users\\\\derek\\\\appdata\\\\local\\\\programs\\\\python\\\\python38\\\\lib\\\\site-packages\\\\click\\\\core.py\", line 1259, in invoke\\n    return _process_result(sub_ctx.command.invoke(sub_ctx))\\n  File \"c:\\\\users\\\\derek\\\\appdata\\\\local\\\\programs\\\\python\\\\python38\\\\lib\\\\site-packages\\\\click\\\\core.py\", line 1066, in invoke\\n    return ctx.invoke(self.callback, **ctx.params)\\n  File \"c:\\\\users\\\\derek\\\\appdata\\\\local\\\\programs\\\\python\\\\python38\\\\lib\\\\site-packages\\\\click\\\\core.py\", line 610, in invoke\\n    return callback(*args, **kwargs)\\n  File \"c:\\\\users\\\\derek\\\\appdata\\\\local\\\\programs\\\\python\\\\python38\\\\lib\\\\site-packages\\\\meltano\\\\cli\\\\params.py\", line 23, in decorate\\n    return func(*args, **kwargs)\\n  File \"c:\\\\users\\\\derek\\\\appdata\\\\local\\\\programs\\\\python\\\\python38\\\\lib\\\\site-packages\\\\meltano\\\\cli\\\\params.py\", line 57, in decorate\\n    func(project, *args, **kwargs)\\n  File \"c:\\\\users\\\\derek\\\\appdata\\\\local\\\\programs\\\\python\\\\python38\\\\lib\\\\site-packages\\\\meltano\\\\cli\\\\elt.py\", line 137, in elt\\n    run_async(_run_job(project, job, session, context_builder, force=force))\\n  File \"c:\\\\users\\\\derek\\\\appdata\\\\local\\\\programs\\\\python\\\\python38\\\\lib\\\\site-packages\\\\meltano\\\\core\\\\utils\\\\__init__.py\", line 39, in run_async\\n    loop.run_until_complete(future)\\n  File \"c:\\\\users\\\\derek\\\\appdata\\\\local\\\\programs\\\\python\\\\python38\\\\lib\\\\asyncio\\\\base_events.py\", line 603, in run_until_complete\\n    self.run_forever()\\n  File \"c:\\\\users\\\\derek\\\\appdata\\\\local\\\\programs\\\\python\\\\python38\\\\lib\\\\asyncio\\\\windows_events.py\", line 316, in run_forever\\n    super().run_forever()\\n  File \"c:\\\\users\\\\derek\\\\appdata\\\\local\\\\programs\\\\python\\\\python38\\\\lib\\\\asyncio\\\\base_events.py\", line 570, in run_forever\\n    self._run_once()\\n  File \"c:\\\\users\\\\derek\\\\appdata\\\\local\\\\programs\\\\python\\\\python38\\\\lib\\\\asyncio\\\\base_events.py\", line 1851, in _run_once\\n    handle._run()\\n  File \"c:\\\\users\\\\derek\\\\appdata\\\\local\\\\programs\\\\python\\\\python38\\\\lib\\\\asyncio\\\\events.py\", line 81, in _run\\n    self._context.run(self._callback, *self._args)\\n  File \"c:\\\\users\\\\derek\\\\appdata\\\\local\\\\programs\\\\python\\\\python38\\\\lib\\\\site-packages\\\\meltano\\\\cli\\\\elt.py\", line 214, in _run_job\\n    await _run_elt(project, context_builder, output_logger)\\n  File \"c:\\\\users\\\\derek\\\\appdata\\\\local\\\\programs\\\\python\\\\python38\\\\lib\\\\site-packages\\\\meltano\\\\cli\\\\elt.py\", line 232, in _run_elt\\n    async with _redirect_output(output_logger):\\n  File \"c:\\\\users\\\\derek\\\\appdata\\\\local\\\\programs\\\\python\\\\python38\\\\lib\\\\site-packages\\\\async_generator\\\\_util.py\", line 34, in __aenter__\\n    return await self._agen.asend(None)\\n  File \"c:\\\\users\\\\derek\\\\appdata\\\\local\\\\programs\\\\python\\\\python38\\\\lib\\\\site-packages\\\\meltano\\\\cli\\\\elt.py\", line 223, in _redirect_output\\n    async with meltano_stdout.redirect_stdout(), meltano_stderr.redirect_stderr():\\n  File \"c:\\\\users\\\\derek\\\\appdata\\\\local\\\\programs\\\\python\\\\python38\\\\lib\\\\site-packages\\\\async_generator\\\\_util.py\", line 34, in __aenter__\\n    return await self._agen.asend(None)\\n  File \"c:\\\\users\\\\derek\\\\appdata\\\\local\\\\programs\\\\python\\\\python38\\\\lib\\\\site-packages\\\\meltano\\\\core\\\\logging\\\\output_logger.py\", line 161, in redirect_stdout\\n    async with self.writer() as stdout:\\n  File \"c:\\\\users\\\\derek\\\\appdata\\\\local\\\\programs\\\\python\\\\python38\\\\lib\\\\site-packages\\\\async_generator\\\\_util.py\", line 34, in __aenter__\\n    return await self._agen.asend(None)\\n  File \"c:\\\\users\\\\derek\\\\appdata\\\\local\\\\programs\\\\python\\\\python38\\\\lib\\\\site-packages\\\\meltano\\\\core\\\\logging\\\\output_logger.py\", line 148, in writer\\n    reader = asyncio.ensure_future(self._read_from_fd(read_fd))\\ntask: <Task pending name=\\'Task-3\\' coro=<Out._read_from_fd() running at c:\\\\users\\\\derek\\\\appdata\\\\local\\\\programs\\\\python\\\\python38\\\\lib\\\\site-packages\\\\meltano\\\\core\\\\logging\\\\output_logger.py:205> wait_for=<Future pending cb=[<TaskWakeupMethWrapper object at 0x000001A9531164F0>()] created at c:\\\\users\\\\derek\\\\appdata\\\\local\\\\programs\\\\python\\\\python38\\\\lib\\\\asyncio\\\\base_events.py:422> created at c:\\\\users\\\\derek\\\\appdata\\\\local\\\\programs\\\\python\\\\python38\\\\lib\\\\site-packages\\\\meltano\\\\core\\\\logging\\\\output_logger.py:148>'\nArguments: ()\nmeltano          | ERROR Task was destroyed but it is pending!\nsource_traceback: Object created at (most recent call last):\n  File \"c:\\users\\derek\\appdata\\local\\programs\\python\\python38\\lib\\runpy.py\", line 194, in _run_module_as_main\n    return _run_code(code, main_globals, None,\n  File \"c:\\users\\derek\\appdata\\local\\programs\\python\\python38\\lib\\runpy.py\", line 87, in _run_code\n    exec(code, run_globals)\n  File \"C:\\Users\\derek\\AppData\\Local\\Programs\\Python\\Python38\\Scripts\\meltano.exe\\__main__.py\", line 7, in <module>\n    sys.exit(main())\n  File \"c:\\users\\derek\\appdata\\local\\programs\\python\\python38\\lib\\site-packages\\meltano\\cli\\__init__.py\", line 43, in main\n    cli(obj={\"project\": None})\n  File \"c:\\users\\derek\\appdata\\local\\programs\\python\\python38\\lib\\site-packages\\click\\core.py\", line 829, in __call__\n    return self.main(*args, **kwargs)\n  File \"c:\\users\\derek\\appdata\\local\\programs\\python\\python38\\lib\\site-packages\\click\\core.py\", line 782, in main\n    rv = self.invoke(ctx)\n  File \"c:\\users\\derek\\appdata\\local\\programs\\python\\python38\\lib\\site-packages\\click\\core.py\", line 1259, in invoke\n    return _process_result(sub_ctx.command.invoke(sub_ctx))\n  File \"c:\\users\\derek\\appdata\\local\\programs\\python\\python38\\lib\\site-packages\\click\\core.py\", line 1066, in invoke\n    return ctx.invoke(self.callback, **ctx.params)\n  File \"c:\\users\\derek\\appdata\\local\\programs\\python\\python38\\lib\\site-packages\\click\\core.py\", line 610, in invoke\n    return callback(*args, **kwargs)\n  File \"c:\\users\\derek\\appdata\\local\\programs\\python\\python38\\lib\\site-packages\\meltano\\cli\\params.py\", line 23, in decorate\n    return func(*args, **kwargs)\n  File \"c:\\users\\derek\\appdata\\local\\programs\\python\\python38\\lib\\site-packages\\meltano\\cli\\params.py\", line 57, in decorate\n    func(project, *args, **kwargs)\n  File \"c:\\users\\derek\\appdata\\local\\programs\\python\\python38\\lib\\site-packages\\meltano\\cli\\elt.py\", line 137, in elt\n    run_async(_run_job(project, job, session, context_builder, force=force))\n  File \"c:\\users\\derek\\appdata\\local\\programs\\python\\python38\\lib\\site-packages\\meltano\\core\\utils\\__init__.py\", line 39, in run_async\n    loop.run_until_complete(future)\n  File \"c:\\users\\derek\\appdata\\local\\programs\\python\\python38\\lib\\asyncio\\base_events.py\", line 603, in run_until_complete\n    self.run_forever()\n  File \"c:\\users\\derek\\appdata\\local\\programs\\python\\python38\\lib\\asyncio\\windows_events.py\", line 316, in run_forever\n    super().run_forever()\n  File \"c:\\users\\derek\\appdata\\local\\programs\\python\\python38\\lib\\asyncio\\base_events.py\", line 570, in run_forever\n    self._run_once()\n  File \"c:\\users\\derek\\appdata\\local\\programs\\python\\python38\\lib\\asyncio\\base_events.py\", line 1851, in _run_once\n    handle._run()\n  File \"c:\\users\\derek\\appdata\\local\\programs\\python\\python38\\lib\\asyncio\\events.py\", line 81, in _run\n    self._context.run(self._callback, *self._args)\n  File \"c:\\users\\derek\\appdata\\local\\programs\\python\\python38\\lib\\site-packages\\meltano\\cli\\elt.py\", line 214, in _run_job\n    await _run_elt(project, context_builder, output_logger)\n  File \"c:\\users\\derek\\appdata\\local\\programs\\python\\python38\\lib\\site-packages\\meltano\\cli\\elt.py\", line 232, in _run_elt\n    async with _redirect_output(output_logger):\n  File \"c:\\users\\derek\\appdata\\local\\programs\\python\\python38\\lib\\site-packages\\async_generator\\_util.py\", line 34, in __aenter__\n    return await self._agen.asend(None)\n  File \"c:\\users\\derek\\appdata\\local\\programs\\python\\python38\\lib\\site-packages\\meltano\\cli\\elt.py\", line 223, in _redirect_output\n    async with meltano_stdout.redirect_stdout(), meltano_stderr.redirect_stderr():\n  File \"c:\\users\\derek\\appdata\\local\\programs\\python\\python38\\lib\\site-packages\\async_generator\\_util.py\", line 34, in __aenter__\n    return await self._agen.asend(None)\n  File \"c:\\users\\derek\\appdata\\local\\programs\\python\\python38\\lib\\site-packages\\meltano\\core\\logging\\output_logger.py\", line 167, in redirect_stderr\n    async with self.writer() as stderr:\n  File \"c:\\users\\derek\\appdata\\local\\programs\\python\\python38\\lib\\site-packages\\async_generator\\_util.py\", line 34, in __aenter__\n    return await self._agen.asend(None)\n  File \"c:\\users\\derek\\appdata\\local\\programs\\python\\python38\\lib\\site-packages\\meltano\\core\\logging\\output_logger.py\", line 148, in writer\n    reader = asyncio.ensure_future(self._read_from_fd(read_fd))\ntask: <Task pending name='Task-4' coro=<Out._read_from_fd() running at c:\\users\\derek\\appdata\\local\\programs\\python\\python38\\lib\\site-packages\\meltano\\core\\logging\\output_logger.py:205> wait_for=<Future pending cb=[<TaskWakeupMethWrapper object at 0x000001A9530B7CA0>()] created at c:\\users\\derek\\appdata\\local\\programs\\python\\python38\\lib\\asyncio\\base_events.py:422> cb=[<TaskWakeupMethWrapper object at 0x000001A953330040>()] created at c:\\users\\derek\\appdata\\local\\programs\\python\\python38\\lib\\site-packages\\meltano\\core\\logging\\output_logger.py:148>\n--- Logging error ---\nTraceback (most recent call last):\n  File \"c:\\users\\derek\\appdata\\local\\programs\\python\\python38\\lib\\logging\\__init__.py\", line 1084, in emit\n    stream.write(msg + self.terminator)\n  File \"c:\\users\\derek\\appdata\\local\\programs\\python\\python38\\lib\\site-packages\\meltano\\core\\logging\\output_logger.py\", line 65, in write\n    self.__out.writeline(line)\n  File \"c:\\users\\derek\\appdata\\local\\programs\\python\\python38\\lib\\site-packages\\meltano\\core\\logging\\output_logger.py\", line 174, in writeline\n    click.echo(self.prefix + line, nl=False, file=self)\n  File \"c:\\users\\derek\\appdata\\local\\programs\\python\\python38\\lib\\site-packages\\click\\utils.py\", line 272, in echo\n    file.write(message)\n  File \"c:\\users\\derek\\appdata\\local\\programs\\python\\python38\\lib\\site-packages\\click\\_compat.py\", line 710, in _safe_write\n    return _write(s)\n  File \"c:\\users\\derek\\appdata\\local\\programs\\python\\python38\\lib\\site-packages\\colorama\\ansitowin32.py\", line 41, in write\n    self.__convertor.write(text)\n  File \"c:\\users\\derek\\appdata\\local\\programs\\python\\python38\\lib\\site-packages\\colorama\\ansitowin32.py\", line 164, in write\n    self.wrapped.write(text)\n  File \"c:\\users\\derek\\appdata\\local\\programs\\python\\python38\\lib\\site-packages\\meltano\\core\\logging\\output_logger.py\", line 179, in write\n    self.file.write(remove_ansi_escape_sequences(data))\nValueError: I/O operation on closed file.\nCall stack:\n  File \"c:\\users\\derek\\appdata\\local\\programs\\python\\python38\\lib\\asyncio\\base_events.py\", line 1733, in call_exception_handler\n    self.default_exception_handler(context)\n  File \"c:\\users\\derek\\appdata\\local\\programs\\python\\python38\\lib\\asyncio\\base_events.py\", line 1707, in default_exception_handler\n    logger.error('\\n'.join(log_lines), exc_info=exc_info)\nMessage: 'Task was destroyed but it is pending!\\nsource_traceback: Object created at (most recent call last):\\n  File \"c:\\\\users\\\\derek\\\\appdata\\\\local\\\\programs\\\\python\\\\python38\\\\lib\\\\runpy.py\", line 194, in _run_module_as_main\\n    return _run_code(code, main_globals, None,\\n  File \"c:\\\\users\\\\derek\\\\appdata\\\\local\\\\programs\\\\python\\\\python38\\\\lib\\\\runpy.py\", line 87, in _run_code\\n    exec(code, run_globals)\\n  File \"C:\\\\Users\\\\derek\\\\AppData\\\\Local\\\\Programs\\\\Python\\\\Python38\\\\Scripts\\\\meltano.exe\\\\__main__.py\", line 7, in <module>\\n    sys.exit(main())\\n  File \"c:\\\\users\\\\derek\\\\appdata\\\\local\\\\programs\\\\python\\\\python38\\\\lib\\\\site-packages\\\\meltano\\\\cli\\\\__init__.py\", line 43, in main\\n    cli(obj={\"project\": None})\\n  File \"c:\\\\users\\\\derek\\\\appdata\\\\local\\\\programs\\\\python\\\\python38\\\\lib\\\\site-packages\\\\click\\\\core.py\", line 829, in __call__\\n    return self.main(*args, **kwargs)\\n  File \"c:\\\\users\\\\derek\\\\appdata\\\\local\\\\programs\\\\python\\\\python38\\\\lib\\\\site-packages\\\\click\\\\core.py\", line 782, in main\\n    rv = self.invoke(ctx)\\n  File \"c:\\\\users\\\\derek\\\\appdata\\\\local\\\\programs\\\\python\\\\python38\\\\lib\\\\site-packages\\\\click\\\\core.py\", line 1259, in invoke\\n    return _process_result(sub_ctx.command.invoke(sub_ctx))\\n  File \"c:\\\\users\\\\derek\\\\appdata\\\\local\\\\programs\\\\python\\\\python38\\\\lib\\\\site-packages\\\\click\\\\core.py\", line 1066, in invoke\\n    return ctx.invoke(self.callback, **ctx.params)\\n  File \"c:\\\\users\\\\derek\\\\appdata\\\\local\\\\programs\\\\python\\\\python38\\\\lib\\\\site-packages\\\\click\\\\core.py\", line 610, in invoke\\n    return callback(*args, **kwargs)\\n  File \"c:\\\\users\\\\derek\\\\appdata\\\\local\\\\programs\\\\python\\\\python38\\\\lib\\\\site-packages\\\\meltano\\\\cli\\\\params.py\", line 23, in decorate\\n    return func(*args, **kwargs)\\n  File \"c:\\\\users\\\\derek\\\\appdata\\\\local\\\\programs\\\\python\\\\python38\\\\lib\\\\site-packages\\\\meltano\\\\cli\\\\params.py\", line 57, in decorate\\n    func(project, *args, **kwargs)\\n  File \"c:\\\\users\\\\derek\\\\appdata\\\\local\\\\programs\\\\python\\\\python38\\\\lib\\\\site-packages\\\\meltano\\\\cli\\\\elt.py\", line 137, in elt\\n    run_async(_run_job(project, job, session, context_builder, force=force))\\n  File \"c:\\\\users\\\\derek\\\\appdata\\\\local\\\\programs\\\\python\\\\python38\\\\lib\\\\site-packages\\\\meltano\\\\core\\\\utils\\\\__init__.py\", line 39, in run_async\\n    loop.run_until_complete(future)\\n  File \"c:\\\\users\\\\derek\\\\appdata\\\\local\\\\programs\\\\python\\\\python38\\\\lib\\\\asyncio\\\\base_events.py\", line 603, in run_until_complete\\n    self.run_forever()\\n  File \"c:\\\\users\\\\derek\\\\appdata\\\\local\\\\programs\\\\python\\\\python38\\\\lib\\\\asyncio\\\\windows_events.py\", line 316, in run_forever\\n    super().run_forever()\\n  File \"c:\\\\users\\\\derek\\\\appdata\\\\local\\\\programs\\\\python\\\\python38\\\\lib\\\\asyncio\\\\base_events.py\", line 570, in run_forever\\n    self._run_once()\\n  File \"c:\\\\users\\\\derek\\\\appdata\\\\local\\\\programs\\\\python\\\\python38\\\\lib\\\\asyncio\\\\base_events.py\", line 1851, in _run_once\\n    handle._run()\\n  File \"c:\\\\users\\\\derek\\\\appdata\\\\local\\\\programs\\\\python\\\\python38\\\\lib\\\\asyncio\\\\events.py\", line 81, in _run\\n    self._context.run(self._callback, *self._args)\\n  File \"c:\\\\users\\\\derek\\\\appdata\\\\local\\\\programs\\\\python\\\\python38\\\\lib\\\\site-packages\\\\meltano\\\\cli\\\\elt.py\", line 214, in _run_job\\n    await _run_elt(project, context_builder, output_logger)\\n  File \"c:\\\\users\\\\derek\\\\appdata\\\\local\\\\programs\\\\python\\\\python38\\\\lib\\\\site-packages\\\\meltano\\\\cli\\\\elt.py\", line 232, in _run_elt\\n    async with _redirect_output(output_logger):\\n  File \"c:\\\\users\\\\derek\\\\appdata\\\\local\\\\programs\\\\python\\\\python38\\\\lib\\\\site-packages\\\\async_generator\\\\_util.py\", line 34, in __aenter__\\n    return await self._agen.asend(None)\\n  File \"c:\\\\users\\\\derek\\\\appdata\\\\local\\\\programs\\\\python\\\\python38\\\\lib\\\\site-packages\\\\meltano\\\\cli\\\\elt.py\", line 223, in _redirect_output\\n    async with meltano_stdout.redirect_stdout(), meltano_stderr.redirect_stderr():\\n  File \"c:\\\\users\\\\derek\\\\appdata\\\\local\\\\programs\\\\python\\\\python38\\\\lib\\\\site-packages\\\\async_generator\\\\_util.py\", line 34, in __aenter__\\n    return await self._agen.asend(None)\\n  File \"c:\\\\users\\\\derek\\\\appdata\\\\local\\\\programs\\\\python\\\\python38\\\\lib\\\\site-packages\\\\meltano\\\\core\\\\logging\\\\output_logger.py\", line 167, in redirect_stderr\\n    async with self.writer() as stderr:\\n  File \"c:\\\\users\\\\derek\\\\appdata\\\\local\\\\programs\\\\python\\\\python38\\\\lib\\\\site-packages\\\\async_generator\\\\_util.py\", line 34, in __aenter__\\n    return await self._agen.asend(None)\\n  File \"c:\\\\users\\\\derek\\\\appdata\\\\local\\\\programs\\\\python\\\\python38\\\\lib\\\\site-packages\\\\meltano\\\\core\\\\logging\\\\output_logger.py\", line 148, in writer\\n    reader = asyncio.ensure_future(self._read_from_fd(read_fd))\\ntask: <Task pending name=\\'Task-4\\' coro=<Out._read_from_fd() running at c:\\\\users\\\\derek\\\\appdata\\\\local\\\\programs\\\\python\\\\python38\\\\lib\\\\site-packages\\\\meltano\\\\core\\\\logging\\\\output_logger.py:205> wait_for=<Future pending cb=[<TaskWakeupMethWrapper object at 0x000001A9530B7CA0>()] created at c:\\\\users\\\\derek\\\\appdata\\\\local\\\\programs\\\\python\\\\python38\\\\lib\\\\asyncio\\\\base_events.py:422> cb=[<TaskWakeupMethWrapper object at 0x000001A953330040>()] created at c:\\\\users\\\\derek\\\\appdata\\\\local\\\\programs\\\\python\\\\python38\\\\lib\\\\site-packages\\\\meltano\\\\core\\\\logging\\\\output_logger.py:148>'\nArguments: ()\nException ignored in: <coroutine object _AsyncGeneratorContextManager.__aexit__ at 0x000001A953180AC0>\nTraceback (most recent call last):\n  File \"c:\\users\\derek\\appdata\\local\\programs\\python\\python38\\lib\\site-packages\\async_generator\\_util.py\", line 84, in __aexit__\n    raise\n  File \"c:\\users\\derek\\appdata\\local\\programs\\python\\python38\\lib\\site-packages\\async_generator\\_util.py\", line 14, in __aexit__\n    await self._aiter.aclose()\nRuntimeError: aclose(): asynchronous generator is already running\nException ignored in: <coroutine object _AsyncGeneratorContextManager.__aexit__ at 0x000001A953180DC0>\nTraceback (most recent call last):\n  File \"c:\\users\\derek\\appdata\\local\\programs\\python\\python38\\lib\\site-packages\\async_generator\\_util.py\", line 84, in __aexit__\n    raise\n  File \"c:\\users\\derek\\appdata\\local\\programs\\python\\python38\\lib\\site-packages\\async_generator\\_util.py\", line 14, in __aexit__\n    await self._aiter.aclose()\nRuntimeError: aclose(): asynchronous generator is already running\n```\n\n\n\n**Output of the same command with a problem reading my catalog file** (ignore the catalog errors, and you'll see the asyncio issues). When there's an issue in the tap asyncio tends to blow up on you with the waiter issue being brought up. Maybe there's something to do with the handling of a tap failure?\n\n```\nPS C:\\code\\meltano-windowstest2> meltano --log-level=debug elt tap-oracle target-csv\n[2021-05-05 14:04:38,856] [21520|MainThread|root] [DEBUG] Creating engine <meltano.core.project.Project object at 0x000001F96C087970>@sqlite:///C:\\code\\meltano-windowstest2/.meltano/meltano.db\n[2021-05-05 14:04:38,888] [21520|MainThread|asyncio] [DEBUG] Using proactor: IocpProactor\nmeltano | DEBUG Starting new HTTPS connection (1): www.meltano.com:443\nmeltano | DEBUG https://www.meltano.com:443 \"GET /discovery.yml?project_id=1281de93-235e-4185-85ce-2b3555a991ae HTTP/1.1\" 200 103053\nmeltano | DEBUG Variable '$MELTANO_LOAD_SCHEMA' is missing from the environment.\nmeltano          | INFO Running extract & load...\nmeltano          | DEBUG Created configuration at C:\\code\\meltano-windowstest2\\.meltano\\run\\elt\\2021-05-05T180438--tap-oracle--target-csv\\8b145347-43c8-402e-ac5f-1e297b0e2f0a\\tap.config.json\nmeltano          | DEBUG Could not find tap.properties.json in C:\\code\\meltano-windowstest2\\.meltano\\extractors\\tap-oracle\\tap.properties.json, skipping.\nmeltano          | DEBUG Could not find tap.properties.cache_key in C:\\code\\meltano-windowstest2\\.meltano\\extractors\\tap-oracle\\tap.properties.cache_key, skipping.\nmeltano          | DEBUG Could not find state.json in C:\\code\\meltano-windowstest2\\.meltano\\extractors\\tap-oracle\\state.json, skipping.\nmeltano          | DEBUG Variable '$MELTANO_LOAD_SCHEMA' is missing from the environment.\nmeltano          | DEBUG Variable '$MELTANO_LOAD_SCHEMA' is missing from the environment.\nmeltano          | DEBUG Created configuration at C:\\code\\meltano-windowstest2\\.meltano\\run\\elt\\2021-05-05T180438--tap-oracle--target-csv\\8b145347-43c8-402e-ac5f-1e297b0e2f0a\\target.config.json\nmeltano          | WARNING No state was found, complete import.\nmeltano          | INFO Found catalog in C:\\code\\meltano-windowstest2\\powerschoolcatalog.json\nmeltano          | DEBUG Deleted configuration at C:\\code\\meltano-windowstest2\\.meltano\\run\\elt\\2021-05-05T180438--tap-oracle--target-csv\\8b145347-43c8-402e-ac5f-1e297b0e2f0a\\target.config.json\nmeltano          | DEBUG Deleted configuration at C:\\code\\meltano-windowstest2\\.meltano\\run\\elt\\2021-05-05T180438--tap-oracle--target-csv\\8b145347-43c8-402e-ac5f-1e297b0e2f0a\\tap.config.json\nmeltano          | DEBUG ELT could not be completed: Cannot start extractor: Catalog discovery failed: invalid catalog: Expecting value: line 1 column 1 (char 0)\nTraceback (most recent call last):\n  File \"c:\\users\\derek\\appdata\\local\\programs\\python\\python38\\lib\\site-packages\\meltano\\core\\plugin\\singer\\tap.py\", line 263, in discover_catalog\n    catalog = json.load(catalog_file)\n  File \"c:\\users\\derek\\appdata\\local\\programs\\python\\python38\\lib\\json\\__init__.py\", line 293, in load\n    return loads(fp.read(),\n  File \"c:\\users\\derek\\appdata\\local\\programs\\python\\python38\\lib\\json\\__init__.py\", line 357, in loads\n    return _default_decoder.decode(s)\n  File \"c:\\users\\derek\\appdata\\local\\programs\\python\\python38\\lib\\json\\decoder.py\", line 337, in decode\n    obj, end = self.raw_decode(s, idx=_w(s, 0).end())\n  File \"c:\\users\\derek\\appdata\\local\\programs\\python\\python38\\lib\\json\\decoder.py\", line 355, in raw_decode\n    raise JSONDecodeError(\"Expecting value\", s, err.value) from None\njson.decoder.JSONDecodeError: Expecting value: line 1 column 1 (char 0)\n\nThe above exception was the direct cause of the following exception:\n\nTraceback (most recent call last):\n  File \"c:\\users\\derek\\appdata\\local\\programs\\python\\python38\\lib\\site-packages\\meltano\\core\\runner\\singer.py\", line 95, in invoke\n    p_tap = await tap.invoke_async(\n  File \"c:\\users\\derek\\appdata\\local\\programs\\python\\python38\\lib\\site-packages\\meltano\\core\\plugin_invoker.py\", line 231, in invoke_async\n    with self._invoke(*args, **kwargs) as (popen_args, popen_options, popen_env):\n  File \"c:\\users\\derek\\appdata\\local\\programs\\python\\python38\\lib\\contextlib.py\", line 113, in __enter__\n    return next(self.gen)\n  File \"c:\\users\\derek\\appdata\\local\\programs\\python\\python38\\lib\\site-packages\\meltano\\core\\plugin_invoker.py\", line 212, in _invoke\n    with self.plugin.trigger_hooks(\"invoke\", self, args):\n  File \"c:\\users\\derek\\appdata\\local\\programs\\python\\python38\\lib\\contextlib.py\", line 113, in __enter__\n    return next(self.gen)\n  File \"c:\\users\\derek\\appdata\\local\\programs\\python\\python38\\lib\\site-packages\\meltano\\core\\behavior\\hookable.py\", line 70, in trigger_hooks\n    self.__class__.trigger(self, f\"before_{hook_name}\", *args, **kwargs)\n  File \"c:\\users\\derek\\appdata\\local\\programs\\python\\python38\\lib\\site-packages\\meltano\\core\\behavior\\hookable.py\", line 97, in trigger\n    raise err\n  File \"c:\\users\\derek\\appdata\\local\\programs\\python\\python38\\lib\\site-packages\\meltano\\core\\behavior\\hookable.py\", line 89, in trigger\n    hook_func(target, *args, **kwargs)\n  File \"c:\\users\\derek\\appdata\\local\\programs\\python\\python38\\lib\\site-packages\\meltano\\core\\plugin\\singer\\tap.py\", line 217, in discover_catalog_hook\n    self.discover_catalog(plugin_invoker, exec_args)\n  File \"c:\\users\\derek\\appdata\\local\\programs\\python\\python38\\lib\\site-packages\\meltano\\core\\plugin\\singer\\tap.py\", line 267, in discover_catalog\n    raise PluginExecutionError(\nmeltano.core.plugin.error.PluginExecutionError: Catalog discovery failed: invalid catalog: Expecting value: line 1 column 1 (char 0)\n\nThe above exception was the direct cause of the following exception:\n\nTraceback (most recent call last):\n  File \"c:\\users\\derek\\appdata\\local\\programs\\python\\python38\\lib\\site-packages\\meltano\\cli\\elt.py\", line 237, in _run_elt\n    await _run_extract_load(elt_context, output_logger)\n  File \"c:\\users\\derek\\appdata\\local\\programs\\python\\python38\\lib\\site-packages\\meltano\\cli\\elt.py\", line 275, in _run_extract_load\n    await singer_runner.run(\n  File \"c:\\users\\derek\\appdata\\local\\programs\\python\\python38\\lib\\site-packages\\meltano\\core\\runner\\singer.py\", line 257, in run\n    await self.invoke(\n  File \"c:\\users\\derek\\appdata\\local\\programs\\python\\python38\\lib\\site-packages\\meltano\\core\\runner\\singer.py\", line 101, in invoke\n    raise RunnerError(f\"Cannot start extractor: {err}\") from err\nmeltano.core.runner.RunnerError: Cannot start extractor: Catalog discovery failed: invalid catalog: Expecting value: line 1 column 1 (char 0)\n\nThe above exception was the direct cause of the following exception:\n\nTraceback (most recent call last):\n  File \"c:\\users\\derek\\appdata\\local\\programs\\python\\python38\\lib\\site-packages\\meltano\\cli\\elt.py\", line 225, in _redirect_output\n    yield\n  File \"c:\\users\\derek\\appdata\\local\\programs\\python\\python38\\lib\\site-packages\\meltano\\cli\\elt.py\", line 246, in _run_elt\n    raise CliError(f\"ELT could not be completed: {err}\") from err\nmeltano.cli.utils.CliError: ELT could not be completed: Cannot start extractor: Catalog discovery failed: invalid catalog: Expecting value: line 1 column 1 (char 0)\nmeltano          | WARNING Executing <Task pending name='Task-1' coro=<_run_job() running at c:\\users\\derek\\appdata\\local\\programs\\python\\python38\\lib\\site-packages\\meltano\\cli\\elt.py:214> wait_for=<Task pending name='Task-4' coro=<Out._read_from_fd() running at c:\\users\\derek\\appdata\\local\\programs\\python\\python38\\lib\\site-packages\\meltano\\core\\logging\\output_logger.py:192> cb=[<TaskWakeupMethWrapper object at 0x000001F972E2D9A0>()] created at c:\\users\\derek\\appdata\\local\\programs\\python\\python38\\lib\\site-packages\\meltano\\core\\logging\\output_logger.py:148> cb=[_run_until_complete_cb() at c:\\users\\derek\\appdata\\local\\programs\\python\\python38\\lib\\asyncio\\base_events.py:184] created at c:\\users\\derek\\appdata\\local\\programs\\python\\python38\\lib\\site-packages\\meltano\\core\\utils\\__init__.py:37> took 1.000 seconds\nmeltano          | DEBUG <_ProactorReadPipeTransport fd=4>: Fatal read error on pipe transport\nTraceback (most recent call last):\n  File \"c:\\users\\derek\\appdata\\local\\programs\\python\\python38\\lib\\asyncio\\proactor_events.py\", line 299, in _loop_reading\n    self._read_fut = self._loop._proactor.recv(self._sock, 32768)\n  File \"c:\\users\\derek\\appdata\\local\\programs\\python\\python38\\lib\\asyncio\\windows_events.py\", line 445, in recv\n    self._register_with_iocp(conn)\n  File \"c:\\users\\derek\\appdata\\local\\programs\\python\\python38\\lib\\asyncio\\windows_events.py\", line 718, in _register_with_iocp\n    _overlapped.CreateIoCompletionPort(obj.fileno(), self._iocp, 0, 0)\nOSError: [WinError 87] The parameter is incorrect\nmeltano          | ERROR Exception in callback _ProactorReadPipeTransport._loop_reading()\nhandle: <Handle _ProactorReadPipeTransport._loop_reading() created at c:\\users\\derek\\appdata\\local\\programs\\python\\python38\\lib\\asyncio\\proactor_events.py:187>\nsource_traceback: Object created at (most recent call last):\n  File \"c:\\users\\derek\\appdata\\local\\programs\\python\\python38\\lib\\asyncio\\windows_events.py\", line 316, in run_forever\n    super().run_forever()\n  File \"c:\\users\\derek\\appdata\\local\\programs\\python\\python38\\lib\\asyncio\\base_events.py\", line 570, in run_forever\n    self._run_once()\n  File \"c:\\users\\derek\\appdata\\local\\programs\\python\\python38\\lib\\asyncio\\base_events.py\", line 1851, in _run_once\n    handle._run()\n  File \"c:\\users\\derek\\appdata\\local\\programs\\python\\python38\\lib\\asyncio\\events.py\", line 81, in _run\n    self._context.run(self._callback, *self._args)\n  File \"c:\\users\\derek\\appdata\\local\\programs\\python\\python38\\lib\\site-packages\\meltano\\core\\logging\\output_logger.py\", line 201, in _read_from_fd\n    read_transport, _ = await loop.connect_read_pipe(\n  File \"c:\\users\\derek\\appdata\\local\\programs\\python\\python38\\lib\\asyncio\\base_events.py\", line 1525, in connect_read_pipe\n    transport = self._make_read_pipe_transport(pipe, protocol, waiter)\n  File \"c:\\users\\derek\\appdata\\local\\programs\\python\\python38\\lib\\asyncio\\proactor_events.py\", line 664, in _make_read_pipe_transport\n    return _ProactorReadPipeTransport(self, sock, protocol, waiter, extra)\n  File \"c:\\users\\derek\\appdata\\local\\programs\\python\\python38\\lib\\asyncio\\proactor_events.py\", line 187, in __init__\n    self._loop.call_soon(self._loop_reading)\nTraceback (most recent call last):\n  File \"c:\\users\\derek\\appdata\\local\\programs\\python\\python38\\lib\\asyncio\\proactor_events.py\", line 299, in _loop_reading\n    self._read_fut = self._loop._proactor.recv(self._sock, 32768)\n  File \"c:\\users\\derek\\appdata\\local\\programs\\python\\python38\\lib\\asyncio\\windows_events.py\", line 445, in recv\n    self._register_with_iocp(conn)\n  File \"c:\\users\\derek\\appdata\\local\\programs\\python\\python38\\lib\\asyncio\\windows_events.py\", line 718, in _register_with_iocp\n    _overlapped.CreateIoCompletionPort(obj.fileno(), self._iocp, 0, 0)\nOSError: [WinError 87] The parameter is incorrect\n\nDuring handling of the above exception, another exception occurred:\n\nTraceback (most recent call last):\n  File \"c:\\users\\derek\\appdata\\local\\programs\\python\\python38\\lib\\asyncio\\events.py\", line 81, in _run\n    self._context.run(self._callback, *self._args)\n  File \"c:\\users\\derek\\appdata\\local\\programs\\python\\python38\\lib\\asyncio\\proactor_events.py\", line 309, in _loop_reading\n    self._fatal_error(exc, 'Fatal read error on pipe transport')\n  File \"c:\\users\\derek\\appdata\\local\\programs\\python\\python38\\lib\\asyncio\\proactor_events.py\", line 131, in _fatal_error\n    self._force_close(exc)\n  File \"c:\\users\\derek\\appdata\\local\\programs\\python\\python38\\lib\\asyncio\\proactor_events.py\", line 134, in _force_close\n    if self._empty_waiter is not None and not self._empty_waiter.done():\nAttributeError: '_ProactorReadPipeTransport' object has no attribute '_empty_waiter'\nmeltano          | DEBUG <_ProactorReadPipeTransport fd=6>: Fatal read error on pipe transport\nTraceback (most recent call last):\n  File \"c:\\users\\derek\\appdata\\local\\programs\\python\\python38\\lib\\asyncio\\proactor_events.py\", line 299, in _loop_reading\n    self._read_fut = self._loop._proactor.recv(self._sock, 32768)\n  File \"c:\\users\\derek\\appdata\\local\\programs\\python\\python38\\lib\\asyncio\\windows_events.py\", line 445, in recv\n    self._register_with_iocp(conn)\n  File \"c:\\users\\derek\\appdata\\local\\programs\\python\\python38\\lib\\asyncio\\windows_events.py\", line 718, in _register_with_iocp\n    _overlapped.CreateIoCompletionPort(obj.fileno(), self._iocp, 0, 0)\nOSError: [WinError 87] The parameter is incorrect\nmeltano          | ERROR Exception in callback _ProactorReadPipeTransport._loop_reading()\nhandle: <Handle _ProactorReadPipeTransport._loop_reading() created at c:\\users\\derek\\appdata\\local\\programs\\python\\python38\\lib\\asyncio\\proactor_events.py:187>\nsource_traceback: Object created at (most recent call last):\n  File \"c:\\users\\derek\\appdata\\local\\programs\\python\\python38\\lib\\asyncio\\windows_events.py\", line 316, in run_forever\n    super().run_forever()\n  File \"c:\\users\\derek\\appdata\\local\\programs\\python\\python38\\lib\\asyncio\\base_events.py\", line 570, in run_forever\n    self._run_once()\n  File \"c:\\users\\derek\\appdata\\local\\programs\\python\\python38\\lib\\asyncio\\base_events.py\", line 1851, in _run_once\n    handle._run()\n  File \"c:\\users\\derek\\appdata\\local\\programs\\python\\python38\\lib\\asyncio\\events.py\", line 81, in _run\n    self._context.run(self._callback, *self._args)\n  File \"c:\\users\\derek\\appdata\\local\\programs\\python\\python38\\lib\\site-packages\\meltano\\core\\logging\\output_logger.py\", line 201, in _read_from_fd\n    read_transport, _ = await loop.connect_read_pipe(\n  File \"c:\\users\\derek\\appdata\\local\\programs\\python\\python38\\lib\\asyncio\\base_events.py\", line 1525, in connect_read_pipe\n    transport = self._make_read_pipe_transport(pipe, protocol, waiter)\n  File \"c:\\users\\derek\\appdata\\local\\programs\\python\\python38\\lib\\asyncio\\proactor_events.py\", line 664, in _make_read_pipe_transport\n    return _ProactorReadPipeTransport(self, sock, protocol, waiter, extra)\n  File \"c:\\users\\derek\\appdata\\local\\programs\\python\\python38\\lib\\asyncio\\proactor_events.py\", line 187, in __init__\n    self._loop.call_soon(self._loop_reading)\nTraceback (most recent call last):\n  File \"c:\\users\\derek\\appdata\\local\\programs\\python\\python38\\lib\\asyncio\\proactor_events.py\", line 299, in _loop_reading\n    self._read_fut = self._loop._proactor.recv(self._sock, 32768)\n  File \"c:\\users\\derek\\appdata\\local\\programs\\python\\python38\\lib\\asyncio\\windows_events.py\", line 445, in recv\n    self._register_with_iocp(conn)\n  File \"c:\\users\\derek\\appdata\\local\\programs\\python\\python38\\lib\\asyncio\\windows_events.py\", line 718, in _register_with_iocp\n    _overlapped.CreateIoCompletionPort(obj.fileno(), self._iocp, 0, 0)\nOSError: [WinError 87] The parameter is incorrect\n\nDuring handling of the above exception, another exception occurred:\n\nTraceback (most recent call last):\n  File \"c:\\users\\derek\\appdata\\local\\programs\\python\\python38\\lib\\asyncio\\events.py\", line 81, in _run\n    self._context.run(self._callback, *self._args)\n  File \"c:\\users\\derek\\appdata\\local\\programs\\python\\python38\\lib\\asyncio\\proactor_events.py\", line 309, in _loop_reading\n    self._fatal_error(exc, 'Fatal read error on pipe transport')\n  File \"c:\\users\\derek\\appdata\\local\\programs\\python\\python38\\lib\\asyncio\\proactor_events.py\", line 131, in _fatal_error\n    self._force_close(exc)\n  File \"c:\\users\\derek\\appdata\\local\\programs\\python\\python38\\lib\\asyncio\\proactor_events.py\", line 134, in _force_close\n    if self._empty_waiter is not None and not self._empty_waiter.done():\nAttributeError: '_ProactorReadPipeTransport' object has no attribute '_empty_waiter'\nmeltano          | DEBUG Read pipe 4 connected: (<_ProactorReadPipeTransport fd=4>, <asyncio.streams.StreamReaderProtocol object at 0x000001F972CF7B20>)\nmeltano          | DEBUG Read pipe 6 connected: (<_ProactorReadPipeTransport fd=6>, <asyncio.streams.StreamReaderProtocol object at 0x000001F972CF7CD0>)\n\nAborted!\nException ignored in: <coroutine object _run_job at 0x000001F972C520C0>\nRuntimeError: coroutine ignored GeneratorExit\nmeltano          | ERROR Task was destroyed but it is pending!\nsource_traceback: Object created at (most recent call last):\n  File \"c:\\users\\derek\\appdata\\local\\programs\\python\\python38\\lib\\runpy.py\", line 194, in _run_module_as_main\n    return _run_code(code, main_globals, None,\n  File \"c:\\users\\derek\\appdata\\local\\programs\\python\\python38\\lib\\runpy.py\", line 87, in _run_code\n    exec(code, run_globals)\n  File \"C:\\Users\\derek\\AppData\\Local\\Programs\\Python\\Python38\\Scripts\\meltano.exe\\__main__.py\", line 7, in <module>\n    sys.exit(main())\n  File \"c:\\users\\derek\\appdata\\local\\programs\\python\\python38\\lib\\site-packages\\meltano\\cli\\__init__.py\", line 43, in main\n    cli(obj={\"project\": None})\n  File \"c:\\users\\derek\\appdata\\local\\programs\\python\\python38\\lib\\site-packages\\click\\core.py\", line 829, in __call__\n    return self.main(*args, **kwargs)\n  File \"c:\\users\\derek\\appdata\\local\\programs\\python\\python38\\lib\\site-packages\\click\\core.py\", line 782, in main\n    rv = self.invoke(ctx)\n  File \"c:\\users\\derek\\appdata\\local\\programs\\python\\python38\\lib\\site-packages\\click\\core.py\", line 1259, in invoke\n    return _process_result(sub_ctx.command.invoke(sub_ctx))\n  File \"c:\\users\\derek\\appdata\\local\\programs\\python\\python38\\lib\\site-packages\\click\\core.py\", line 1066, in invoke\n    return ctx.invoke(self.callback, **ctx.params)\n  File \"c:\\users\\derek\\appdata\\local\\programs\\python\\python38\\lib\\site-packages\\click\\core.py\", line 610, in invoke\n    return callback(*args, **kwargs)\n  File \"c:\\users\\derek\\appdata\\local\\programs\\python\\python38\\lib\\site-packages\\meltano\\cli\\params.py\", line 23, in decorate\n    return func(*args, **kwargs)\n  File \"c:\\users\\derek\\appdata\\local\\programs\\python\\python38\\lib\\site-packages\\meltano\\cli\\params.py\", line 57, in decorate\n    func(project, *args, **kwargs)\n  File \"c:\\users\\derek\\appdata\\local\\programs\\python\\python38\\lib\\site-packages\\meltano\\cli\\elt.py\", line 137, in elt\n    run_async(_run_job(project, job, session, context_builder, force=force))\n  File \"c:\\users\\derek\\appdata\\local\\programs\\python\\python38\\lib\\site-packages\\meltano\\core\\utils\\__init__.py\", line 37, in run_async\n    future = asyncio.ensure_future(coro)\ntask: <Task pending name='Task-1' coro=<_run_job() running at c:\\users\\derek\\appdata\\local\\programs\\python\\python38\\lib\\site-packages\\meltano\\cli\\elt.py:214> wait_for=<Task pending name='Task-4' coro=<Out._read_from_fd() running at c:\\users\\derek\\appdata\\local\\programs\\python\\python38\\lib\\site-packages\\meltano\\core\\logging\\output_logger.py:205> wait_for=<Future pending cb=[<TaskWakeupMethWrapper object at 0x000001F972CF7CA0>()] created at c:\\users\\derek\\appdata\\local\\programs\\python\\python38\\lib\\asyncio\\base_events.py:422> cb=[<TaskWakeupMethWrapper object at 0x000001F972E2D9A0>()] created at c:\\users\\derek\\appdata\\local\\programs\\python\\python38\\lib\\site-packages\\meltano\\core\\logging\\output_logger.py:148> created at c:\\users\\derek\\appdata\\local\\programs\\python\\python38\\lib\\site-packages\\meltano\\core\\utils\\__init__.py:37>\n--- Logging error ---\nTraceback (most recent call last):\n  File \"c:\\users\\derek\\appdata\\local\\programs\\python\\python38\\lib\\logging\\__init__.py\", line 1084, in emit\n    stream.write(msg + self.terminator)\n  File \"c:\\users\\derek\\appdata\\local\\programs\\python\\python38\\lib\\site-packages\\meltano\\core\\logging\\output_logger.py\", line 65, in write\n    self.__out.writeline(line)\n  File \"c:\\users\\derek\\appdata\\local\\programs\\python\\python38\\lib\\site-packages\\meltano\\core\\logging\\output_logger.py\", line 174, in writeline\n    click.echo(self.prefix + line, nl=False, file=self)\n  File \"c:\\users\\derek\\appdata\\local\\programs\\python\\python38\\lib\\site-packages\\click\\utils.py\", line 272, in echo\n    file.write(message)\n  File \"c:\\users\\derek\\appdata\\local\\programs\\python\\python38\\lib\\site-packages\\click\\_compat.py\", line 710, in _safe_write\n    return _write(s)\n  File \"c:\\users\\derek\\appdata\\local\\programs\\python\\python38\\lib\\site-packages\\colorama\\ansitowin32.py\", line 41, in write\n    self.__convertor.write(text)\n  File \"c:\\users\\derek\\appdata\\local\\programs\\python\\python38\\lib\\site-packages\\colorama\\ansitowin32.py\", line 164, in write\n    self.wrapped.write(text)\n  File \"c:\\users\\derek\\appdata\\local\\programs\\python\\python38\\lib\\site-packages\\meltano\\core\\logging\\output_logger.py\", line 179, in write\n    self.file.write(remove_ansi_escape_sequences(data))\nValueError: I/O operation on closed file.\nCall stack:\n  File \"c:\\users\\derek\\appdata\\local\\programs\\python\\python38\\lib\\asyncio\\base_events.py\", line 1733, in call_exception_handler\n    self.default_exception_handler(context)\n  File \"c:\\users\\derek\\appdata\\local\\programs\\python\\python38\\lib\\asyncio\\base_events.py\", line 1707, in default_exception_handler\n    logger.error('\\n'.join(log_lines), exc_info=exc_info)\nMessage: 'Task was destroyed but it is pending!\\nsource_traceback: Object created at (most recent call last):\\n  File \"c:\\\\users\\\\derek\\\\appdata\\\\local\\\\programs\\\\python\\\\python38\\\\lib\\\\runpy.py\", line 194, in _run_module_as_main\\n    return _run_code(code, main_globals, None,\\n  File \"c:\\\\users\\\\derek\\\\appdata\\\\local\\\\programs\\\\python\\\\python38\\\\lib\\\\runpy.py\", line 87, in _run_code\\n    exec(code, run_globals)\\n  File \"C:\\\\Users\\\\derek\\\\AppData\\\\Local\\\\Programs\\\\Python\\\\Python38\\\\Scripts\\\\meltano.exe\\\\__main__.py\", line 7, in <module>\\n    sys.exit(main())\\n  File \"c:\\\\users\\\\derek\\\\appdata\\\\local\\\\programs\\\\python\\\\python38\\\\lib\\\\site-packages\\\\meltano\\\\cli\\\\__init__.py\", line 43, in main\\n    cli(obj={\"project\": None})\\n  File \"c:\\\\users\\\\derek\\\\appdata\\\\local\\\\programs\\\\python\\\\python38\\\\lib\\\\site-packages\\\\click\\\\core.py\", line 829, in __call__\\n    return self.main(*args, **kwargs)\\n  File \"c:\\\\users\\\\derek\\\\appdata\\\\local\\\\programs\\\\python\\\\python38\\\\lib\\\\site-packages\\\\click\\\\core.py\", line 782, in main\\n    rv = self.invoke(ctx)\\n  File \"c:\\\\users\\\\derek\\\\appdata\\\\local\\\\programs\\\\python\\\\python38\\\\lib\\\\site-packages\\\\click\\\\core.py\", line 1259, in invoke\\n    return _process_result(sub_ctx.command.invoke(sub_ctx))\\n  File \"c:\\\\users\\\\derek\\\\appdata\\\\local\\\\programs\\\\python\\\\python38\\\\lib\\\\site-packages\\\\click\\\\core.py\", line 1066, in invoke\\n    return ctx.invoke(self.callback, **ctx.params)\\n  File \"c:\\\\users\\\\derek\\\\appdata\\\\local\\\\programs\\\\python\\\\python38\\\\lib\\\\site-packages\\\\click\\\\core.py\", line 610, in invoke\\n    return callback(*args, **kwargs)\\n  File \"c:\\\\users\\\\derek\\\\appdata\\\\local\\\\programs\\\\python\\\\python38\\\\lib\\\\site-packages\\\\meltano\\\\cli\\\\params.py\", line 23, in decorate\\n    return func(*args, **kwargs)\\n  File \"c:\\\\users\\\\derek\\\\appdata\\\\local\\\\programs\\\\python\\\\python38\\\\lib\\\\site-packages\\\\meltano\\\\cli\\\\params.py\", line 57, in decorate\\n    func(project, *args, **kwargs)\\n  File \"c:\\\\users\\\\derek\\\\appdata\\\\local\\\\programs\\\\python\\\\python38\\\\lib\\\\site-packages\\\\meltano\\\\cli\\\\elt.py\", line 137, in elt\\n    run_async(_run_job(project, job, session, context_builder, force=force))\\n  File \"c:\\\\users\\\\derek\\\\appdata\\\\local\\\\programs\\\\python\\\\python38\\\\lib\\\\site-packages\\\\meltano\\\\core\\\\utils\\\\__init__.py\", line 37, in run_async\\n    future = asyncio.ensure_future(coro)\\ntask: <Task pending name=\\'Task-1\\' coro=<_run_job() running at c:\\\\users\\\\derek\\\\appdata\\\\local\\\\programs\\\\python\\\\python38\\\\lib\\\\site-packages\\\\meltano\\\\cli\\\\elt.py:214> wait_for=<Task pending name=\\'Task-4\\' coro=<Out._read_from_fd() running at c:\\\\users\\\\derek\\\\appdata\\\\local\\\\programs\\\\python\\\\python38\\\\lib\\\\site-packages\\\\meltano\\\\core\\\\logging\\\\output_logger.py:205> wait_for=<Future pending cb=[<TaskWakeupMethWrapper object at 0x000001F972CF7CA0>()] created at c:\\\\users\\\\derek\\\\appdata\\\\local\\\\programs\\\\python\\\\python38\\\\lib\\\\asyncio\\\\base_events.py:422> cb=[<TaskWakeupMethWrapper object at 0x000001F972E2D9A0>()] created at c:\\\\users\\\\derek\\\\appdata\\\\local\\\\programs\\\\python\\\\python38\\\\lib\\\\site-packages\\\\meltano\\\\core\\\\logging\\\\output_logger.py:148> created at c:\\\\users\\\\derek\\\\appdata\\\\local\\\\programs\\\\python\\\\python38\\\\lib\\\\site-packages\\\\meltano\\\\core\\\\utils\\\\__init__.py:37>'\nArguments: ()\nException ignored in: <generator object Job._handling_sigterm at 0x000001F972CD6AC0>\nTraceback (most recent call last):\n  File \"c:\\users\\derek\\appdata\\local\\programs\\python\\python38\\lib\\site-packages\\meltano\\core\\job\\job.py\", line 229, in _handling_sigterm\n    signal.signal(signal.SIGTERM, original_termination_handler)\n  File \"c:\\users\\derek\\appdata\\local\\programs\\python\\python38\\lib\\signal.py\", line 47, in signal\n    handler = _signal.signal(_enum_to_int(signalnum), _enum_to_int(handler))\nTypeError: signal handler must be signal.SIG_IGN, signal.SIG_DFL, or a callable object\nmeltano          | ERROR Task was destroyed but it is pending!\nsource_traceback: Object created at (most recent call last):\n  File \"c:\\users\\derek\\appdata\\local\\programs\\python\\python38\\lib\\runpy.py\", line 194, in _run_module_as_main\n    return _run_code(code, main_globals, None,\n  File \"c:\\users\\derek\\appdata\\local\\programs\\python\\python38\\lib\\runpy.py\", line 87, in _run_code\n    exec(code, run_globals)\n  File \"C:\\Users\\derek\\AppData\\Local\\Programs\\Python\\Python38\\Scripts\\meltano.exe\\__main__.py\", line 7, in <module>\n    sys.exit(main())\n  File \"c:\\users\\derek\\appdata\\local\\programs\\python\\python38\\lib\\site-packages\\meltano\\cli\\__init__.py\", line 43, in main\n    cli(obj={\"project\": None})\n  File \"c:\\users\\derek\\appdata\\local\\programs\\python\\python38\\lib\\site-packages\\click\\core.py\", line 829, in __call__\n    return self.main(*args, **kwargs)\n  File \"c:\\users\\derek\\appdata\\local\\programs\\python\\python38\\lib\\site-packages\\click\\core.py\", line 782, in main\n    rv = self.invoke(ctx)\n  File \"c:\\users\\derek\\appdata\\local\\programs\\python\\python38\\lib\\site-packages\\click\\core.py\", line 1259, in invoke\n    return _process_result(sub_ctx.command.invoke(sub_ctx))\n  File \"c:\\users\\derek\\appdata\\local\\programs\\python\\python38\\lib\\site-packages\\click\\core.py\", line 1066, in invoke\n    return ctx.invoke(self.callback, **ctx.params)\n  File \"c:\\users\\derek\\appdata\\local\\programs\\python\\python38\\lib\\site-packages\\click\\core.py\", line 610, in invoke\n    return callback(*args, **kwargs)\n  File \"c:\\users\\derek\\appdata\\local\\programs\\python\\python38\\lib\\site-packages\\meltano\\cli\\params.py\", line 23, in decorate\n    return func(*args, **kwargs)\n  File \"c:\\users\\derek\\appdata\\local\\programs\\python\\python38\\lib\\site-packages\\meltano\\cli\\params.py\", line 57, in decorate\n    func(project, *args, **kwargs)\n  File \"c:\\users\\derek\\appdata\\local\\programs\\python\\python38\\lib\\site-packages\\meltano\\cli\\elt.py\", line 137, in elt\n    run_async(_run_job(project, job, session, context_builder, force=force))\n  File \"c:\\users\\derek\\appdata\\local\\programs\\python\\python38\\lib\\site-packages\\meltano\\core\\utils\\__init__.py\", line 39, in run_async\n    loop.run_until_complete(future)\n  File \"c:\\users\\derek\\appdata\\local\\programs\\python\\python38\\lib\\asyncio\\base_events.py\", line 603, in run_until_complete\n    self.run_forever()\n  File \"c:\\users\\derek\\appdata\\local\\programs\\python\\python38\\lib\\asyncio\\windows_events.py\", line 316, in run_forever\n    super().run_forever()\n  File \"c:\\users\\derek\\appdata\\local\\programs\\python\\python38\\lib\\asyncio\\base_events.py\", line 570, in run_forever\n    self._run_once()\n  File \"c:\\users\\derek\\appdata\\local\\programs\\python\\python38\\lib\\asyncio\\base_events.py\", line 1851, in _run_once\n    handle._run()\n  File \"c:\\users\\derek\\appdata\\local\\programs\\python\\python38\\lib\\asyncio\\events.py\", line 81, in _run\n    self._context.run(self._callback, *self._args)\n  File \"c:\\users\\derek\\appdata\\local\\programs\\python\\python38\\lib\\site-packages\\meltano\\cli\\elt.py\", line 214, in _run_job\n    await _run_elt(project, context_builder, output_logger)\n  File \"c:\\users\\derek\\appdata\\local\\programs\\python\\python38\\lib\\site-packages\\meltano\\cli\\elt.py\", line 232, in _run_elt\n    async with _redirect_output(output_logger):\n  File \"c:\\users\\derek\\appdata\\local\\programs\\python\\python38\\lib\\site-packages\\async_generator\\_util.py\", line 34, in __aenter__\n    return await self._agen.asend(None)\n  File \"c:\\users\\derek\\appdata\\local\\programs\\python\\python38\\lib\\site-packages\\meltano\\cli\\elt.py\", line 223, in _redirect_output\n    async with meltano_stdout.redirect_stdout(), meltano_stderr.redirect_stderr():\n  File \"c:\\users\\derek\\appdata\\local\\programs\\python\\python38\\lib\\site-packages\\async_generator\\_util.py\", line 34, in __aenter__\n    return await self._agen.asend(None)\n  File \"c:\\users\\derek\\appdata\\local\\programs\\python\\python38\\lib\\site-packages\\meltano\\core\\logging\\output_logger.py\", line 161, in redirect_stdout\n    async with self.writer() as stdout:\n  File \"c:\\users\\derek\\appdata\\local\\programs\\python\\python38\\lib\\site-packages\\async_generator\\_util.py\", line 34, in __aenter__\n    return await self._agen.asend(None)\n  File \"c:\\users\\derek\\appdata\\local\\programs\\python\\python38\\lib\\site-packages\\meltano\\core\\logging\\output_logger.py\", line 148, in writer\n    reader = asyncio.ensure_future(self._read_from_fd(read_fd))\ntask: <Task pending name='Task-3' coro=<Out._read_from_fd() running at c:\\users\\derek\\appdata\\local\\programs\\python\\python38\\lib\\site-packages\\meltano\\core\\logging\\output_logger.py:205> wait_for=<Future pending cb=[<TaskWakeupMethWrapper object at 0x000001F972CF7AF0>()] created at c:\\users\\derek\\appdata\\local\\programs\\python\\python38\\lib\\asyncio\\base_events.py:422> created at c:\\users\\derek\\appdata\\local\\programs\\python\\python38\\lib\\site-packages\\meltano\\core\\logging\\output_logger.py:148>\n--- Logging error ---\nTraceback (most recent call last):\n  File \"c:\\users\\derek\\appdata\\local\\programs\\python\\python38\\lib\\logging\\__init__.py\", line 1084, in emit\n    stream.write(msg + self.terminator)\n  File \"c:\\users\\derek\\appdata\\local\\programs\\python\\python38\\lib\\site-packages\\meltano\\core\\logging\\output_logger.py\", line 65, in write\n    self.__out.writeline(line)\n  File \"c:\\users\\derek\\appdata\\local\\programs\\python\\python38\\lib\\site-packages\\meltano\\core\\logging\\output_logger.py\", line 174, in writeline\n    click.echo(self.prefix + line, nl=False, file=self)\n  File \"c:\\users\\derek\\appdata\\local\\programs\\python\\python38\\lib\\site-packages\\click\\utils.py\", line 272, in echo\n    file.write(message)\n  File \"c:\\users\\derek\\appdata\\local\\programs\\python\\python38\\lib\\site-packages\\click\\_compat.py\", line 710, in _safe_write\n    return _write(s)\n  File \"c:\\users\\derek\\appdata\\local\\programs\\python\\python38\\lib\\site-packages\\colorama\\ansitowin32.py\", line 41, in write\n    self.__convertor.write(text)\n  File \"c:\\users\\derek\\appdata\\local\\programs\\python\\python38\\lib\\site-packages\\colorama\\ansitowin32.py\", line 164, in write\n    self.wrapped.write(text)\n  File \"c:\\users\\derek\\appdata\\local\\programs\\python\\python38\\lib\\site-packages\\meltano\\core\\logging\\output_logger.py\", line 179, in write\n    self.file.write(remove_ansi_escape_sequences(data))\nValueError: I/O operation on closed file.\nCall stack:\n  File \"c:\\users\\derek\\appdata\\local\\programs\\python\\python38\\lib\\asyncio\\base_events.py\", line 1733, in call_exception_handler\n    self.default_exception_handler(context)\n  File \"c:\\users\\derek\\appdata\\local\\programs\\python\\python38\\lib\\asyncio\\base_events.py\", line 1707, in default_exception_handler\n    logger.error('\\n'.join(log_lines), exc_info=exc_info)\nMessage: 'Task was destroyed but it is pending!\\nsource_traceback: Object created at (most recent call last):\\n  File \"c:\\\\users\\\\derek\\\\appdata\\\\local\\\\programs\\\\python\\\\python38\\\\lib\\\\runpy.py\", line 194, in _run_module_as_main\\n    return _run_code(code, main_globals, None,\\n  File \"c:\\\\users\\\\derek\\\\appdata\\\\local\\\\programs\\\\python\\\\python38\\\\lib\\\\runpy.py\", line 87, in _run_code\\n    exec(code, run_globals)\\n  File \"C:\\\\Users\\\\derek\\\\AppData\\\\Local\\\\Programs\\\\Python\\\\Python38\\\\Scripts\\\\meltano.exe\\\\__main__.py\", line 7, in <module>\\n    sys.exit(main())\\n  File \"c:\\\\users\\\\derek\\\\appdata\\\\local\\\\programs\\\\python\\\\python38\\\\lib\\\\site-packages\\\\meltano\\\\cli\\\\__init__.py\", line 43, in main\\n    cli(obj={\"project\": None})\\n  File \"c:\\\\users\\\\derek\\\\appdata\\\\local\\\\programs\\\\python\\\\python38\\\\lib\\\\site-packages\\\\click\\\\core.py\", line 829, in __call__\\n    return self.main(*args, **kwargs)\\n  File \"c:\\\\users\\\\derek\\\\appdata\\\\local\\\\programs\\\\python\\\\python38\\\\lib\\\\site-packages\\\\click\\\\core.py\", line 782, in main\\n    rv = self.invoke(ctx)\\n  File \"c:\\\\users\\\\derek\\\\appdata\\\\local\\\\programs\\\\python\\\\python38\\\\lib\\\\site-packages\\\\click\\\\core.py\", line 1259, in invoke\\n    return _process_result(sub_ctx.command.invoke(sub_ctx))\\n  File \"c:\\\\users\\\\derek\\\\appdata\\\\local\\\\programs\\\\python\\\\python38\\\\lib\\\\site-packages\\\\click\\\\core.py\", line 1066, in invoke\\n    return ctx.invoke(self.callback, **ctx.params)\\n  File \"c:\\\\users\\\\derek\\\\appdata\\\\local\\\\programs\\\\python\\\\python38\\\\lib\\\\site-packages\\\\click\\\\core.py\", line 610, in invoke\\n    return callback(*args, **kwargs)\\n  File \"c:\\\\users\\\\derek\\\\appdata\\\\local\\\\programs\\\\python\\\\python38\\\\lib\\\\site-packages\\\\meltano\\\\cli\\\\params.py\", line 23, in decorate\\n    return func(*args, **kwargs)\\n  File \"c:\\\\users\\\\derek\\\\appdata\\\\local\\\\programs\\\\python\\\\python38\\\\lib\\\\site-packages\\\\meltano\\\\cli\\\\params.py\", line 57, in decorate\\n    func(project, *args, **kwargs)\\n  File \"c:\\\\users\\\\derek\\\\appdata\\\\local\\\\programs\\\\python\\\\python38\\\\lib\\\\site-packages\\\\meltano\\\\cli\\\\elt.py\", line 137, in elt\\n    run_async(_run_job(project, job, session, context_builder, force=force))\\n  File \"c:\\\\users\\\\derek\\\\appdata\\\\local\\\\programs\\\\python\\\\python38\\\\lib\\\\site-packages\\\\meltano\\\\core\\\\utils\\\\__init__.py\", line 39, in run_async\\n    loop.run_until_complete(future)\\n  File \"c:\\\\users\\\\derek\\\\appdata\\\\local\\\\programs\\\\python\\\\python38\\\\lib\\\\asyncio\\\\base_events.py\", line 603, in run_until_complete\\n    self.run_forever()\\n  File \"c:\\\\users\\\\derek\\\\appdata\\\\local\\\\programs\\\\python\\\\python38\\\\lib\\\\asyncio\\\\windows_events.py\", line 316, in run_forever\\n    super().run_forever()\\n  File \"c:\\\\users\\\\derek\\\\appdata\\\\local\\\\programs\\\\python\\\\python38\\\\lib\\\\asyncio\\\\base_events.py\", line 570, in run_forever\\n    self._run_once()\\n  File \"c:\\\\users\\\\derek\\\\appdata\\\\local\\\\programs\\\\python\\\\python38\\\\lib\\\\asyncio\\\\base_events.py\", line 1851, in _run_once\\n    handle._run()\\n  File \"c:\\\\users\\\\derek\\\\appdata\\\\local\\\\programs\\\\python\\\\python38\\\\lib\\\\asyncio\\\\events.py\", line 81, in _run\\n    self._context.run(self._callback, *self._args)\\n  File \"c:\\\\users\\\\derek\\\\appdata\\\\local\\\\programs\\\\python\\\\python38\\\\lib\\\\site-packages\\\\meltano\\\\cli\\\\elt.py\", line 214, in _run_job\\n    await _run_elt(project, context_builder, output_logger)\\n  File \"c:\\\\users\\\\derek\\\\appdata\\\\local\\\\programs\\\\python\\\\python38\\\\lib\\\\site-packages\\\\meltano\\\\cli\\\\elt.py\", line 232, in _run_elt\\n    async with _redirect_output(output_logger):\\n  File \"c:\\\\users\\\\derek\\\\appdata\\\\local\\\\programs\\\\python\\\\python38\\\\lib\\\\site-packages\\\\async_generator\\\\_util.py\", line 34, in __aenter__\\n    return await self._agen.asend(None)\\n  File \"c:\\\\users\\\\derek\\\\appdata\\\\local\\\\programs\\\\python\\\\python38\\\\lib\\\\site-packages\\\\meltano\\\\cli\\\\elt.py\", line 223, in _redirect_output\\n    async with meltano_stdout.redirect_stdout(), meltano_stderr.redirect_stderr():\\n  File \"c:\\\\users\\\\derek\\\\appdata\\\\local\\\\programs\\\\python\\\\python38\\\\lib\\\\site-packages\\\\async_generator\\\\_util.py\", line 34, in __aenter__\\n    return await self._agen.asend(None)\\n  File \"c:\\\\users\\\\derek\\\\appdata\\\\local\\\\programs\\\\python\\\\python38\\\\lib\\\\site-packages\\\\meltano\\\\core\\\\logging\\\\output_logger.py\", line 161, in redirect_stdout\\n    async with self.writer() as stdout:\\n  File \"c:\\\\users\\\\derek\\\\appdata\\\\local\\\\programs\\\\python\\\\python38\\\\lib\\\\site-packages\\\\async_generator\\\\_util.py\", line 34, in __aenter__\\n    return await self._agen.asend(None)\\n  File \"c:\\\\users\\\\derek\\\\appdata\\\\local\\\\programs\\\\python\\\\python38\\\\lib\\\\site-packages\\\\meltano\\\\core\\\\logging\\\\output_logger.py\", line 148, in writer\\n    reader = asyncio.ensure_future(self._read_from_fd(read_fd))\\ntask: <Task pending name=\\'Task-3\\' coro=<Out._read_from_fd() running at c:\\\\users\\\\derek\\\\appdata\\\\local\\\\programs\\\\python\\\\python38\\\\lib\\\\site-packages\\\\meltano\\\\core\\\\logging\\\\output_logger.py:205> wait_for=<Future pending cb=[<TaskWakeupMethWrapper object at 0x000001F972CF7AF0>()] created at c:\\\\users\\\\derek\\\\appdata\\\\local\\\\programs\\\\python\\\\python38\\\\lib\\\\asyncio\\\\base_events.py:422> created at c:\\\\users\\\\derek\\\\appdata\\\\local\\\\programs\\\\python\\\\python38\\\\lib\\\\site-packages\\\\meltano\\\\core\\\\logging\\\\output_logger.py:148>'\nArguments: ()\nmeltano          | ERROR Task was destroyed but it is pending!\nsource_traceback: Object created at (most recent call last):\n  File \"c:\\users\\derek\\appdata\\local\\programs\\python\\python38\\lib\\runpy.py\", line 194, in _run_module_as_main\n    return _run_code(code, main_globals, None,\n  File \"c:\\users\\derek\\appdata\\local\\programs\\python\\python38\\lib\\runpy.py\", line 87, in _run_code\n    exec(code, run_globals)\n  File \"C:\\Users\\derek\\AppData\\Local\\Programs\\Python\\Python38\\Scripts\\meltano.exe\\__main__.py\", line 7, in <module>\n    sys.exit(main())\n  File \"c:\\users\\derek\\appdata\\local\\programs\\python\\python38\\lib\\site-packages\\meltano\\cli\\__init__.py\", line 43, in main\n    cli(obj={\"project\": None})\n  File \"c:\\users\\derek\\appdata\\local\\programs\\python\\python38\\lib\\site-packages\\click\\core.py\", line 829, in __call__\n    return self.main(*args, **kwargs)\n  File \"c:\\users\\derek\\appdata\\local\\programs\\python\\python38\\lib\\site-packages\\click\\core.py\", line 782, in main\n    rv = self.invoke(ctx)\n  File \"c:\\users\\derek\\appdata\\local\\programs\\python\\python38\\lib\\site-packages\\click\\core.py\", line 1259, in invoke\n    return _process_result(sub_ctx.command.invoke(sub_ctx))\n  File \"c:\\users\\derek\\appdata\\local\\programs\\python\\python38\\lib\\site-packages\\click\\core.py\", line 1066, in invoke\n    return ctx.invoke(self.callback, **ctx.params)\n  File \"c:\\users\\derek\\appdata\\local\\programs\\python\\python38\\lib\\site-packages\\click\\core.py\", line 610, in invoke\n    return callback(*args, **kwargs)\n  File \"c:\\users\\derek\\appdata\\local\\programs\\python\\python38\\lib\\site-packages\\meltano\\cli\\params.py\", line 23, in decorate\n    return func(*args, **kwargs)\n  File \"c:\\users\\derek\\appdata\\local\\programs\\python\\python38\\lib\\site-packages\\meltano\\cli\\params.py\", line 57, in decorate\n    func(project, *args, **kwargs)\n  File \"c:\\users\\derek\\appdata\\local\\programs\\python\\python38\\lib\\site-packages\\meltano\\cli\\elt.py\", line 137, in elt\n    run_async(_run_job(project, job, session, context_builder, force=force))\n  File \"c:\\users\\derek\\appdata\\local\\programs\\python\\python38\\lib\\site-packages\\meltano\\core\\utils\\__init__.py\", line 39, in run_async\n    loop.run_until_complete(future)\n  File \"c:\\users\\derek\\appdata\\local\\programs\\python\\python38\\lib\\asyncio\\base_events.py\", line 603, in run_until_complete\n    self.run_forever()\n  File \"c:\\users\\derek\\appdata\\local\\programs\\python\\python38\\lib\\asyncio\\windows_events.py\", line 316, in run_forever\n    super().run_forever()\n  File \"c:\\users\\derek\\appdata\\local\\programs\\python\\python38\\lib\\asyncio\\base_events.py\", line 570, in run_forever\n    self._run_once()\n  File \"c:\\users\\derek\\appdata\\local\\programs\\python\\python38\\lib\\asyncio\\base_events.py\", line 1851, in _run_once\n    handle._run()\n  File \"c:\\users\\derek\\appdata\\local\\programs\\python\\python38\\lib\\asyncio\\events.py\", line 81, in _run\n    self._context.run(self._callback, *self._args)\n  File \"c:\\users\\derek\\appdata\\local\\programs\\python\\python38\\lib\\site-packages\\meltano\\cli\\elt.py\", line 214, in _run_job\n    await _run_elt(project, context_builder, output_logger)\n  File \"c:\\users\\derek\\appdata\\local\\programs\\python\\python38\\lib\\site-packages\\meltano\\cli\\elt.py\", line 232, in _run_elt\n    async with _redirect_output(output_logger):\n  File \"c:\\users\\derek\\appdata\\local\\programs\\python\\python38\\lib\\site-packages\\async_generator\\_util.py\", line 34, in __aenter__\n    return await self._agen.asend(None)\n  File \"c:\\users\\derek\\appdata\\local\\programs\\python\\python38\\lib\\site-packages\\meltano\\cli\\elt.py\", line 223, in _redirect_output\n    async with meltano_stdout.redirect_stdout(), meltano_stderr.redirect_stderr():\n  File \"c:\\users\\derek\\appdata\\local\\programs\\python\\python38\\lib\\site-packages\\async_generator\\_util.py\", line 34, in __aenter__\n    return await self._agen.asend(None)\n  File \"c:\\users\\derek\\appdata\\local\\programs\\python\\python38\\lib\\site-packages\\meltano\\core\\logging\\output_logger.py\", line 167, in redirect_stderr\n    async with self.writer() as stderr:\n  File \"c:\\users\\derek\\appdata\\local\\programs\\python\\python38\\lib\\site-packages\\async_generator\\_util.py\", line 34, in __aenter__\n    return await self._agen.asend(None)\n  File \"c:\\users\\derek\\appdata\\local\\programs\\python\\python38\\lib\\site-packages\\meltano\\core\\logging\\output_logger.py\", line 148, in writer\n    reader = asyncio.ensure_future(self._read_from_fd(read_fd))\ntask: <Task pending name='Task-4' coro=<Out._read_from_fd() running at c:\\users\\derek\\appdata\\local\\programs\\python\\python38\\lib\\site-packages\\meltano\\core\\logging\\output_logger.py:205> wait_for=<Future pending cb=[<TaskWakeupMethWrapper object at 0x000001F972CF7CA0>()] created at c:\\users\\derek\\appdata\\local\\programs\\python\\python38\\lib\\asyncio\\base_events.py:422> cb=[<TaskWakeupMethWrapper object at 0x000001F972E2D9A0>()] created at c:\\users\\derek\\appdata\\local\\programs\\python\\python38\\lib\\site-packages\\meltano\\core\\logging\\output_logger.py:148>\n--- Logging error ---\nTraceback (most recent call last):\n  File \"c:\\users\\derek\\appdata\\local\\programs\\python\\python38\\lib\\logging\\__init__.py\", line 1084, in emit\n    stream.write(msg + self.terminator)\n  File \"c:\\users\\derek\\appdata\\local\\programs\\python\\python38\\lib\\site-packages\\meltano\\core\\logging\\output_logger.py\", line 65, in write\n    self.__out.writeline(line)\n  File \"c:\\users\\derek\\appdata\\local\\programs\\python\\python38\\lib\\site-packages\\meltano\\core\\logging\\output_logger.py\", line 174, in writeline\n    click.echo(self.prefix + line, nl=False, file=self)\n  File \"c:\\users\\derek\\appdata\\local\\programs\\python\\python38\\lib\\site-packages\\click\\utils.py\", line 272, in echo\n    file.write(message)\n  File \"c:\\users\\derek\\appdata\\local\\programs\\python\\python38\\lib\\site-packages\\click\\_compat.py\", line 710, in _safe_write\n    return _write(s)\n  File \"c:\\users\\derek\\appdata\\local\\programs\\python\\python38\\lib\\site-packages\\colorama\\ansitowin32.py\", line 41, in write\n    self.__convertor.write(text)\n  File \"c:\\users\\derek\\appdata\\local\\programs\\python\\python38\\lib\\site-packages\\colorama\\ansitowin32.py\", line 164, in write\n    self.wrapped.write(text)\n  File \"c:\\users\\derek\\appdata\\local\\programs\\python\\python38\\lib\\site-packages\\meltano\\core\\logging\\output_logger.py\", line 179, in write\n    self.file.write(remove_ansi_escape_sequences(data))\nValueError: I/O operation on closed file.\nCall stack:\n  File \"c:\\users\\derek\\appdata\\local\\programs\\python\\python38\\lib\\asyncio\\base_events.py\", line 1733, in call_exception_handler\n    self.default_exception_handler(context)\n  File \"c:\\users\\derek\\appdata\\local\\programs\\python\\python38\\lib\\asyncio\\base_events.py\", line 1707, in default_exception_handler\n    logger.error('\\n'.join(log_lines), exc_info=exc_info)\nMessage: 'Task was destroyed but it is pending!\\nsource_traceback: Object created at (most recent call last):\\n  File \"c:\\\\users\\\\derek\\\\appdata\\\\local\\\\programs\\\\python\\\\python38\\\\lib\\\\runpy.py\", line 194, in _run_module_as_main\\n    return _run_code(code, main_globals, None,\\n  File \"c:\\\\users\\\\derek\\\\appdata\\\\local\\\\programs\\\\python\\\\python38\\\\lib\\\\runpy.py\", line 87, in _run_code\\n    exec(code, run_globals)\\n  File \"C:\\\\Users\\\\derek\\\\AppData\\\\Local\\\\Programs\\\\Python\\\\Python38\\\\Scripts\\\\meltano.exe\\\\__main__.py\", line 7, in <module>\\n    sys.exit(main())\\n  File \"c:\\\\users\\\\derek\\\\appdata\\\\local\\\\programs\\\\python\\\\python38\\\\lib\\\\site-packages\\\\meltano\\\\cli\\\\__init__.py\", line 43, in main\\n    cli(obj={\"project\": None})\\n  File \"c:\\\\users\\\\derek\\\\appdata\\\\local\\\\programs\\\\python\\\\python38\\\\lib\\\\site-packages\\\\click\\\\core.py\", line 829, in __call__\\n    return self.main(*args, **kwargs)\\n  File \"c:\\\\users\\\\derek\\\\appdata\\\\local\\\\programs\\\\python\\\\python38\\\\lib\\\\site-packages\\\\click\\\\core.py\", line 782, in main\\n    rv = self.invoke(ctx)\\n  File \"c:\\\\users\\\\derek\\\\appdata\\\\local\\\\programs\\\\python\\\\python38\\\\lib\\\\site-packages\\\\click\\\\core.py\", line 1259, in invoke\\n    return _process_result(sub_ctx.command.invoke(sub_ctx))\\n  File \"c:\\\\users\\\\derek\\\\appdata\\\\local\\\\programs\\\\python\\\\python38\\\\lib\\\\site-packages\\\\click\\\\core.py\", line 1066, in invoke\\n    return ctx.invoke(self.callback, **ctx.params)\\n  File \"c:\\\\users\\\\derek\\\\appdata\\\\local\\\\programs\\\\python\\\\python38\\\\lib\\\\site-packages\\\\click\\\\core.py\", line 610, in invoke\\n    return callback(*args, **kwargs)\\n  File \"c:\\\\users\\\\derek\\\\appdata\\\\local\\\\programs\\\\python\\\\python38\\\\lib\\\\site-packages\\\\meltano\\\\cli\\\\params.py\", line 23, in decorate\\n    return func(*args, **kwargs)\\n  File \"c:\\\\users\\\\derek\\\\appdata\\\\local\\\\programs\\\\python\\\\python38\\\\lib\\\\site-packages\\\\meltano\\\\cli\\\\params.py\", line 57, in decorate\\n    func(project, *args, **kwargs)\\n  File \"c:\\\\users\\\\derek\\\\appdata\\\\local\\\\programs\\\\python\\\\python38\\\\lib\\\\site-packages\\\\meltano\\\\cli\\\\elt.py\", line 137, in elt\\n    run_async(_run_job(project, job, session, context_builder, force=force))\\n  File \"c:\\\\users\\\\derek\\\\appdata\\\\local\\\\programs\\\\python\\\\python38\\\\lib\\\\site-packages\\\\meltano\\\\core\\\\utils\\\\__init__.py\", line 39, in run_async\\n    loop.run_until_complete(future)\\n  File \"c:\\\\users\\\\derek\\\\appdata\\\\local\\\\programs\\\\python\\\\python38\\\\lib\\\\asyncio\\\\base_events.py\", line 603, in run_until_complete\\n    self.run_forever()\\n  File \"c:\\\\users\\\\derek\\\\appdata\\\\local\\\\programs\\\\python\\\\python38\\\\lib\\\\asyncio\\\\windows_events.py\", line 316, in run_forever\\n    super().run_forever()\\n  File \"c:\\\\users\\\\derek\\\\appdata\\\\local\\\\programs\\\\python\\\\python38\\\\lib\\\\asyncio\\\\base_events.py\", line 570, in run_forever\\n    self._run_once()\\n  File \"c:\\\\users\\\\derek\\\\appdata\\\\local\\\\programs\\\\python\\\\python38\\\\lib\\\\asyncio\\\\base_events.py\", line 1851, in _run_once\\n    handle._run()\\n  File \"c:\\\\users\\\\derek\\\\appdata\\\\local\\\\programs\\\\python\\\\python38\\\\lib\\\\asyncio\\\\events.py\", line 81, in _run\\n    self._context.run(self._callback, *self._args)\\n  File \"c:\\\\users\\\\derek\\\\appdata\\\\local\\\\programs\\\\python\\\\python38\\\\lib\\\\site-packages\\\\meltano\\\\cli\\\\elt.py\", line 214, in _run_job\\n    await _run_elt(project, context_builder, output_logger)\\n  File \"c:\\\\users\\\\derek\\\\appdata\\\\local\\\\programs\\\\python\\\\python38\\\\lib\\\\site-packages\\\\meltano\\\\cli\\\\elt.py\", line 232, in _run_elt\\n    async with _redirect_output(output_logger):\\n  File \"c:\\\\users\\\\derek\\\\appdata\\\\local\\\\programs\\\\python\\\\python38\\\\lib\\\\site-packages\\\\async_generator\\\\_util.py\", line 34, in __aenter__\\n    return await self._agen.asend(None)\\n  File \"c:\\\\users\\\\derek\\\\appdata\\\\local\\\\programs\\\\python\\\\python38\\\\lib\\\\site-packages\\\\meltano\\\\cli\\\\elt.py\", line 223, in _redirect_output\\n    async with meltano_stdout.redirect_stdout(), meltano_stderr.redirect_stderr():\\n  File \"c:\\\\users\\\\derek\\\\appdata\\\\local\\\\programs\\\\python\\\\python38\\\\lib\\\\site-packages\\\\async_generator\\\\_util.py\", line 34, in __aenter__\\n    return await self._agen.asend(None)\\n  File \"c:\\\\users\\\\derek\\\\appdata\\\\local\\\\programs\\\\python\\\\python38\\\\lib\\\\site-packages\\\\meltano\\\\core\\\\logging\\\\output_logger.py\", line 167, in redirect_stderr\\n    async with self.writer() as stderr:\\n  File \"c:\\\\users\\\\derek\\\\appdata\\\\local\\\\programs\\\\python\\\\python38\\\\lib\\\\site-packages\\\\async_generator\\\\_util.py\", line 34, in __aenter__\\n    return await self._agen.asend(None)\\n  File \"c:\\\\users\\\\derek\\\\appdata\\\\local\\\\programs\\\\python\\\\python38\\\\lib\\\\site-packages\\\\meltano\\\\core\\\\logging\\\\output_logger.py\", line 148, in writer\\n    reader = asyncio.ensure_future(self._read_from_fd(read_fd))\\ntask: <Task pending name=\\'Task-4\\' coro=<Out._read_from_fd() running at c:\\\\users\\\\derek\\\\appdata\\\\local\\\\programs\\\\python\\\\python38\\\\lib\\\\site-packages\\\\meltano\\\\core\\\\logging\\\\output_logger.py:205> wait_for=<Future pending cb=[<TaskWakeupMethWrapper object at 0x000001F972CF7CA0>()] created at c:\\\\users\\\\derek\\\\appdata\\\\local\\\\programs\\\\python\\\\python38\\\\lib\\\\asyncio\\\\base_events.py:422> cb=[<TaskWakeupMethWrapper object at 0x000001F972E2D9A0>()] created at c:\\\\users\\\\derek\\\\appdata\\\\local\\\\programs\\\\python\\\\python38\\\\lib\\\\site-packages\\\\meltano\\\\core\\\\logging\\\\output_logger.py:148>'\nArguments: ()\nException ignored in: <coroutine object _AsyncGeneratorContextManager.__aexit__ at 0x000001F972D5CF40>\nTraceback (most recent call last):\n  File \"c:\\users\\derek\\appdata\\local\\programs\\python\\python38\\lib\\site-packages\\async_generator\\_util.py\", line 84, in __aexit__\n    raise\n  File \"c:\\users\\derek\\appdata\\local\\programs\\python\\python38\\lib\\site-packages\\async_generator\\_util.py\", line 14, in __aexit__\n    await self._aiter.aclose()\nRuntimeError: aclose(): asynchronous generator is already running\nException ignored in: <coroutine object _AsyncGeneratorContextManager.__aexit__ at 0x000001F972DCA140>\nTraceback (most recent call last):\n  File \"c:\\users\\derek\\appdata\\local\\programs\\python\\python38\\lib\\site-packages\\async_generator\\_util.py\", line 84, in __aexit__\n    raise\n  File \"c:\\users\\derek\\appdata\\local\\programs\\python\\python38\\lib\\site-packages\\async_generator\\_util.py\", line 14, in __aexit__\n    await self._aiter.aclose()\nRuntimeError: aclose(): asynchronous generator is already running\n```",
      "state": "closed",
      "created_at": "2021-05-05T18:18:49.059Z",
      "updated_at": "2022-05-30T22:58:38.887Z",
      "closed_at": "2022-05-30T22:58:38.869Z",
      "closed_by": {
        "id": 11629953,
        "username": "MeltyBot",
        "public_email": "",
        "name": "Melty Bot",
        "state": "active",
        "locked": false,
        "avatar_url": "https://gitlab.com/uploads/-/system/user/avatar/11629953/avatar.png",
        "web_url": "https://gitlab.com/MeltyBot"
      },
      "labels": [
        "Extract",
        "Load",
        "OKR: Improve New User Experience",
        "Windows Support",
        "flow::Doing",
        "kind::Bug",
        "valuestream::Meltano"
      ],
      "milestone": {
        "id": 2351599,
        "iid": 209,
        "group_id": 2524164,
        "title": "May 2022",
        "description": "",
        "state": "active",
        "created_at": "2021-11-29T21:38:23.665Z",
        "updated_at": "2021-11-29T21:38:23.665Z",
        "due_date": "2022-05-31",
        "start_date": "2022-05-01",
        "expired": true,
        "web_url": "https://gitlab.com/groups/meltano/-/milestones/209"
      },
      "assignees": [
        {
          "id": 5562019,
          "username": "vischous",
          "public_email": "",
          "name": "Derek Visch",
          "state": "active",
          "locked": false,
          "avatar_url": "https://gitlab.com/uploads/-/system/user/avatar/5562019/avatar.png",
          "web_url": "https://gitlab.com/vischous"
        }
      ],
      "author": {
        "id": 5562019,
        "username": "vischous",
        "public_email": "",
        "name": "Derek Visch",
        "state": "active",
        "locked": false,
        "avatar_url": "https://gitlab.com/uploads/-/system/user/avatar/5562019/avatar.png",
        "web_url": "https://gitlab.com/vischous"
      },
      "type": "ISSUE",
      "assignee": {
        "id": 5562019,
        "username": "vischous",
        "public_email": "",
        "name": "Derek Visch",
        "state": "active",
        "locked": false,
        "avatar_url": "https://gitlab.com/uploads/-/system/user/avatar/5562019/avatar.png",
        "web_url": "https://gitlab.com/vischous"
      },
      "user_notes_count": 16,
      "merge_requests_count": 1,
      "upvotes": 0,
      "downvotes": 0,
      "due_date": null,
      "confidential": false,
      "discussion_locked": null,
      "issue_type": "issue",
      "web_url": "https://gitlab.com/meltano/meltano/-/issues/2743",
      "time_stats": {
        "time_estimate": 0,
        "total_time_spent": 0,
        "human_time_estimate": null,
        "human_total_time_spent": null
      },
      "task_completion_status": {
        "count": 0,
        "completed_count": 0
      },
      "weight": 4,
      "blocking_issues_count": 0,
      "has_tasks": true,
      "task_status": "0 of 0 checklist items completed",
      "_links": {
        "self": "https://gitlab.com/api/v4/projects/7603319/issues/2743",
        "notes": "https://gitlab.com/api/v4/projects/7603319/issues/2743/notes",
        "award_emoji": "https://gitlab.com/api/v4/projects/7603319/issues/2743/award_emoji",
        "project": "https://gitlab.com/api/v4/projects/7603319",
        "closed_as_duplicate_of": null
      },
      "references": {
        "short": "#2743",
        "relative": "#2743",
        "full": "meltano/meltano#2743"
      },
      "severity": "UNKNOWN",
      "moved_to_id": null,
      "imported": false,
      "imported_from": "none",
      "service_desk_reply_to": null,
      "epic_iid": 115,
      "epic": {
        "id": 329384,
        "iid": 115,
        "title": "Meltano on Windows",
        "url": "/groups/meltano/-/epics/115",
        "group_id": 2524164,
        "human_readable_end_date": "May 31, 2022",
        "human_readable_timestamp": "<strong>Past due</strong>"
      },
      "iteration": {
        "id": 56416,
        "iid": 56,
        "sequence": 3,
        "group_id": 2524164,
        "title": null,
        "description": null,
        "state": 3,
        "created_at": "2022-05-13T20:04:48.839Z",
        "updated_at": "2022-05-30T00:05:02.370Z",
        "start_date": "2022-05-23",
        "due_date": "2022-05-29",
        "web_url": "https://gitlab.com/groups/meltano/-/iterations/56416"
      },
      "health_status": null,
      "epic_issue_id": 858211,
      "relative_position": -2052
    },
    {
      "id": 81051156,
      "iid": 5,
      "project_id": 19558116,
      "title": "Reported bug on Windows (docker): plugins available to select but are not available to run",
      "description": "A user has reported in slack and demoed in a screenshare session that after spinning up the docker container for the project, they were unable to execute a pipeline due a failure that the plugin was not installed. The user reported that if they go through the extra step of logging into the container via command line, and running `meltano install` again, the symptom would be resolved - at least until the process is repeated again on another workstation.\n\nIn our screenshare session, we tried a few different iterations and seemed to have luck by reording the commands within the project's `Dockerfile`. On comparison with this repo, that text did match what we have here.\n\nWe should attempt to reproduce this issue on our side and confirm if a similar adjustment in the Dockerfile resolves the symptom.\n\nWe should also open additional issues if there are improvements we can make in the available documentation.\n\nLink to conversation in slack: https://meltano.slack.com/archives/CFG3C3C66/p1615923950017800?thread_ts=1615473028.130200&cid=CFG3C3C66",
      "state": "closed",
      "created_at": "2021-03-16T19:44:32.800Z",
      "updated_at": "2022-04-05T17:52:13.009Z",
      "closed_at": "2022-04-05T17:52:12.995Z",
      "closed_by": {
        "id": 4809760,
        "username": "aaronsteers",
        "public_email": "aaronsteers@gmail.com",
        "name": "AJ Steers",
        "state": "active",
        "locked": false,
        "avatar_url": "https://secure.gravatar.com/avatar/a2595480c83e2879745276d7beca618e489d7df97677ed44888fd6f0f50efb29?s=80&d=identicon",
        "web_url": "https://gitlab.com/aaronsteers"
      },
      "labels": [
        "Customer Support",
        "flow::Triage",
        "kind::Bug",
        "urgency::default",
        "valuestream::Meltano"
      ],
      "milestone": {
        "id": 797629,
        "iid": 42,
        "group_id": 2524164,
        "title": "Backlog",
        "description": "As a start, I think it would be good to prioritize based on:\r\n- urgency of getting feedback\r\n- relative implementation difficulty\r\n- symbiotic relationships between issues",
        "state": "active",
        "created_at": "2019-02-21T14:50:28.741Z",
        "updated_at": "2019-02-21T14:50:28.741Z",
        "due_date": null,
        "start_date": "2019-02-25",
        "expired": false,
        "web_url": "https://gitlab.com/groups/meltano/-/milestones/42"
      },
      "assignees": [],
      "author": {
        "id": 4809760,
        "username": "aaronsteers",
        "public_email": "aaronsteers@gmail.com",
        "name": "AJ Steers",
        "state": "active",
        "locked": false,
        "avatar_url": "https://secure.gravatar.com/avatar/a2595480c83e2879745276d7beca618e489d7df97677ed44888fd6f0f50efb29?s=80&d=identicon",
        "web_url": "https://gitlab.com/aaronsteers"
      },
      "type": "ISSUE",
      "assignee": null,
      "user_notes_count": 2,
      "merge_requests_count": 0,
      "upvotes": 0,
      "downvotes": 0,
      "due_date": null,
      "confidential": false,
      "discussion_locked": null,
      "issue_type": "issue",
      "web_url": "https://gitlab.com/meltano/files-docker/-/issues/5",
      "time_stats": {
        "time_estimate": 0,
        "total_time_spent": 0,
        "human_time_estimate": null,
        "human_total_time_spent": null
      },
      "task_completion_status": {
        "count": 0,
        "completed_count": 0
      },
      "weight": 4,
      "blocking_issues_count": 0,
      "has_tasks": true,
      "task_status": "0 of 0 checklist items completed",
      "_links": {
        "self": "https://gitlab.com/api/v4/projects/19558116/issues/5",
        "notes": "https://gitlab.com/api/v4/projects/19558116/issues/5/notes",
        "award_emoji": "https://gitlab.com/api/v4/projects/19558116/issues/5/award_emoji",
        "project": "https://gitlab.com/api/v4/projects/19558116",
        "closed_as_duplicate_of": null
      },
      "references": {
        "short": "#5",
        "relative": "#5",
        "full": "meltano/files-docker#5"
      },
      "severity": "UNKNOWN",
      "moved_to_id": null,
      "imported": false,
      "imported_from": "none",
      "service_desk_reply_to": null,
      "epic_iid": 115,
      "epic": {
        "id": 329384,
        "iid": 115,
        "title": "Meltano on Windows",
        "url": "/groups/meltano/-/epics/115",
        "group_id": 2524164,
        "human_readable_end_date": "May 31, 2022",
        "human_readable_timestamp": "<strong>Past due</strong>"
      },
      "iteration": null,
      "health_status": null,
      "epic_issue_id": 971337,
      "relative_position": -2565
    },
    {
      "id": 26704111,
      "iid": 1261,
      "project_id": 7603319,
      "title": "`meltano ui` fails on Windows",
      "description": "**UPDATE: A newer issues is now logged with steps to resolve: https://gitlab.com/meltano/meltano/-/issues/3383+**\n\n**Deduping this issue to consolidate effort there.**\n\nA user shared the following traceback through Intercom:\n\n```\n[MainThread][INFO][2019-11-05 17:42:42,750] Context impl SQLiteImpl.\n[MainThread][INFO][2019-11-05 17:42:42,751] Will assume non-transactional DDL.\nSystem database up-to-date.\nTraceback (most recent call last):\nFile \"C:\\Users\\None\\AppData\\Local\\Programs\\Python\\Python36\\Scripts\\meltano-script.py\", line 11, in <module>\nload_entry_point('meltano==1.4.0', 'console_scripts', 'meltano')()\nFile \"c:\\users\\none\\appdata\\local\\programs\\python\\python36\\lib\\site-packages\\meltano\\cli\\__init__.py\", line 22, in main\ncli(obj={\"project\": None})\nFile \"c:\\users\\none\\appdata\\local\\programs\\python\\python36\\lib\\site-packages\\click\\core.py\", line 764, in __call__\nreturn self.main(*args, **kwargs)\nFile \"c:\\users\\none\\appdata\\local\\programs\\python\\python36\\lib\\site-packages\\click\\core.py\", line 717, in main\nrv = self.invoke(ctx)\nFile \"c:\\users\\none\\appdata\\local\\programs\\python\\python36\\lib\\site-packages\\click\\core.py\", line 1137, in invoke\nreturn _process_result(sub_ctx.command.invoke(sub_ctx))\nFile \"c:\\users\\none\\appdata\\local\\programs\\python\\python36\\lib\\site-packages\\click\\core.py\", line 956, in invoke\nreturn ctx.invoke(self.callback, **ctx.params)\nFile \"c:\\users\\none\\appdata\\local\\programs\\python\\python36\\lib\\site-packages\\click\\core.py\", line 555, in invoke\nreturn callback(*args, **kwargs)\nFile \"c:\\users\\none\\appdata\\local\\programs\\python\\python36\\lib\\site-packages\\meltano\\cli\\params.py\", line 24, in decorate\nreturn func(engine_uri, *args, **kwargs)\nFile \"c:\\users\\none\\appdata\\local\\programs\\python\\python36\\lib\\site-packages\\meltano\\cli\\params.py\", line 55, in decorate\nfunc(project, *args, **kwargs)\nFile \"c:\\users\\none\\appdata\\local\\programs\\python\\python36\\lib\\site-packages\\meltano\\cli\\ui.py\", line 66, in ui\nasyncio.get_child_watcher()\nFile \"c:\\users\\none\\appdata\\local\\programs\\python\\python36\\lib\\asyncio\\events.py\", line 709, in get_child_watcher\nreturn get_event_loop_policy().get_child_watcher()\nFile \"c:\\users\\none\\appdata\\local\\programs\\python\\python36\\lib\\asyncio\\events.py\", line 562, in get_child_watcher\nraise NotImplementedError\nNotImplementedError\n```\n\nYou can see that they are running Windows, and that `asyncio.get_child_watcher` raises `NotImplementedError`.\n\nThis is consistent with [the documentation](https://docs.python.org/3/library/asyncio-policy.html#asyncio.AbstractEventLoopPolicy.get_child_watcher) for that method, which states:\n\n> This function is Unix specific.\n\nCan we make this statement conditional on running on a Unix-like environment, or do we need to find an alternative implementation for Windows?\n\n(Whether or not it makes sense to support Windows at this stage is a different topic, but for now let's assume we do.)",
      "state": "closed",
      "created_at": "2019-11-05T10:36:42.946Z",
      "updated_at": "2022-04-19T17:21:20.405Z",
      "closed_at": "2022-04-19T17:19:36.642Z",
      "closed_by": {
        "id": 4809760,
        "username": "aaronsteers",
        "public_email": "aaronsteers@gmail.com",
        "name": "AJ Steers",
        "state": "active",
        "locked": false,
        "avatar_url": "https://secure.gravatar.com/avatar/a2595480c83e2879745276d7beca618e489d7df97677ed44888fd6f0f50efb29?s=80&d=identicon",
        "web_url": "https://gitlab.com/aaronsteers"
      },
      "labels": [
        "CLI",
        "Configuration",
        "OKR: Improve New User Experience",
        "Windows Support",
        "kind::Bug",
        "valuestream::Meltano"
      ],
      "milestone": {
        "id": 797629,
        "iid": 42,
        "group_id": 2524164,
        "title": "Backlog",
        "description": "As a start, I think it would be good to prioritize based on:\r\n- urgency of getting feedback\r\n- relative implementation difficulty\r\n- symbiotic relationships between issues",
        "state": "active",
        "created_at": "2019-02-21T14:50:28.741Z",
        "updated_at": "2019-02-21T14:50:28.741Z",
        "due_date": null,
        "start_date": "2019-02-25",
        "expired": false,
        "web_url": "https://gitlab.com/groups/meltano/-/milestones/42"
      },
      "assignees": [],
      "author": {
        "id": 87854,
        "username": "DouweM",
        "public_email": "",
        "name": "Douwe Maan",
        "state": "active",
        "locked": false,
        "avatar_url": "https://secure.gravatar.com/avatar/bbb752c75ae2744bddf1640d75edf9b6f7d4e5f4fbba4a4f0910961e6f0519b9?s=80&d=identicon",
        "web_url": "https://gitlab.com/DouweM"
      },
      "type": "ISSUE",
      "assignee": null,
      "user_notes_count": 8,
      "merge_requests_count": 0,
      "upvotes": 0,
      "downvotes": 0,
      "due_date": null,
      "confidential": false,
      "discussion_locked": null,
      "issue_type": "issue",
      "web_url": "https://gitlab.com/meltano/meltano/-/issues/1261",
      "time_stats": {
        "time_estimate": 0,
        "total_time_spent": 0,
        "human_time_estimate": null,
        "human_total_time_spent": null
      },
      "task_completion_status": {
        "count": 0,
        "completed_count": 0
      },
      "weight": null,
      "blocking_issues_count": 0,
      "has_tasks": true,
      "task_status": "0 of 0 checklist items completed",
      "_links": {
        "self": "https://gitlab.com/api/v4/projects/7603319/issues/1261",
        "notes": "https://gitlab.com/api/v4/projects/7603319/issues/1261/notes",
        "award_emoji": "https://gitlab.com/api/v4/projects/7603319/issues/1261/award_emoji",
        "project": "https://gitlab.com/api/v4/projects/7603319",
        "closed_as_duplicate_of": "https://gitlab.com/api/v4/projects/7603319/issues/3383"
      },
      "references": {
        "short": "#1261",
        "relative": "#1261",
        "full": "meltano/meltano#1261"
      },
      "severity": "UNKNOWN",
      "moved_to_id": null,
      "imported": false,
      "imported_from": "none",
      "service_desk_reply_to": null,
      "epic_iid": 115,
      "epic": {
        "id": 329384,
        "iid": 115,
        "title": "Meltano on Windows",
        "url": "/groups/meltano/-/epics/115",
        "group_id": 2524164,
        "human_readable_end_date": "May 31, 2022",
        "human_readable_timestamp": "<strong>Past due</strong>"
      },
      "iteration": null,
      "health_status": null,
      "epic_issue_id": 805897,
      "relative_position": -1026
    },
    {
      "id": 26050728,
      "iid": 1148,
      "project_id": 7603319,
      "title": "ModuleNotFoundError: 'fcntl' on Windows (Gunicorn + meltano ui)",
      "description": "<!---\nPlease read this!\n\nBefore opening a new issue, make sure to search for keywords in the issues\nfiltered by the \"regression\" or \"bug\" label and verify the issue you're about to submit isn't a duplicate.\n\nIf you are submitting an issue with a tap, please include:\n\n- account details\n- target details\n- entities selected  with meltano select (if you have selected any entities), as the bug may be related to a specific entity\n- the full elt command you are running\n- full output of the meltano elt command. Logs can get pretty long, so you can add the full log as a snippet in the Meltano project and add a link in the issue.\n--->\n\n### What is the current *bug* behavior?\n\n\nOn a brand new project and new meltano install on Windows (Windows 10 Insiders with Python3.7) I'm receiving an error about missing the `fcntl` module, and the command fails.\n\n```\nModuleNotFoundError: No module named 'fcntl'\n[AirflowWorker][ERROR][2019-10-17 11:22:26,094] Failed to start plugin <meltano.core.plugin.airflow.Airflow object at 0x000001C93E882438>.\n```\n\n### What is the expected *correct* behavior?\n\nI expect this command to launch the UI server.\n\n\n### Steps to reproduce\n\nOn Windows:\n\n```\npip install meltano\nmeltano init meltano-demo\ncd meltano-demo\nmeltano ui\n```\n\n### Relevant logs and/or screenshots\n_Please use code blocks (\\`\\`\\`) to format console output_\n\n```\n(meltano) c:\\Files\\Source\\dataops-quickstart\\meltano-demo>meltano ui\n[MainThread][INFO][2019-10-17 11:22:25,629] Context impl SQLiteImpl.\n[MainThread][INFO][2019-10-17 11:22:25,630] Will assume non-transactional DDL.\nSystem database up-to-date.\n[MainThread][INFO][2019-10-17 11:22:25,783] Auto-compiling models in 'C:\\Files\\Source\\dataops-quickstart\\meltano-demo\\model'\n[MainThread][INFO][2019-10-17 11:22:25,787] All workers started.\nTraceback (most recent call last):\n  File \"C:\\Python37\\lib\\runpy.py\", line 193, in _run_module_as_main\n    \"__main__\", mod_spec)\n  File \"C:\\Python37\\lib\\runpy.py\", line 85, in _run_code\n    exec(code, run_globals)\n  File \"c:\\Files\\venvs\\meltano\\Scripts\\gunicorn.exe\\__main__.py\", line 5, in <module>\n  File \"c:\\files\\venvs\\meltano\\lib\\site-packages\\gunicorn\\app\\wsgiapp.py\", line 9, in <module>\n    from gunicorn.app.base import Application\n  File \"c:\\files\\venvs\\meltano\\lib\\site-packages\\gunicorn\\app\\base.py\", line 12, in <module>\n    from gunicorn import util\n  File \"c:\\files\\venvs\\meltano\\lib\\site-packages\\gunicorn\\util.py\", line 9, in <module>\n    import fcntl\nModuleNotFoundError: No module named 'fcntl'\n[AirflowWorker][ERROR][2019-10-17 11:22:26,094] Failed to start plugin <meltano.core.plugin.airflow.Airflow object at 0x000001C93E882438>.\nException in thread AirflowWorker:\nTraceback (most recent call last):\n  File \"C:\\Python37\\lib\\threading.py\", line 917, in _bootstrap_inner\n    self.run()\n  File \"c:\\files\\venvs\\meltano\\lib\\site-packages\\meltano\\api\\workers.py\", line 201, in run\n    self.start_all()\n  File \"c:\\files\\venvs\\meltano\\lib\\site-packages\\meltano\\api\\workers.py\", line 177, in start_all\n    self._webserver = invoker.invoke(\"webserver\", \"-w\", \"1\", stdout=webserver)\n  File \"c:\\files\\venvs\\meltano\\lib\\site-packages\\meltano\\core\\plugin_invoker.py\", line 122, in invoke\n    process = subprocess.Popen(popen_args, **Popen_options)\n  File \"C:\\Python37\\lib\\subprocess.py\", line 775, in __init__\n    restore_signals, start_new_session)\n  File \"C:\\Python37\\lib\\subprocess.py\", line 1178, in _execute_child\n    startupinfo)\nFileNotFoundError: [WinError 2] The system cannot find the file specified\n```\n\n### Possible fixes\n\nN/A\n\n\n### Further regression test\n_Ensure we automatically catch similar issues in the future_\n\n- [ ] Write additional adequate test cases and submit test results\n- [ ] Test results should be reviewed by a person from the team",
      "state": "closed",
      "created_at": "2019-10-17T16:37:18.933Z",
      "updated_at": "2022-04-06T15:13:23.443Z",
      "closed_at": "2022-04-05T18:51:33.349Z",
      "closed_by": {
        "id": 4809760,
        "username": "aaronsteers",
        "public_email": "aaronsteers@gmail.com",
        "name": "AJ Steers",
        "state": "active",
        "locked": false,
        "avatar_url": "https://secure.gravatar.com/avatar/a2595480c83e2879745276d7beca618e489d7df97677ed44888fd6f0f50efb29?s=80&d=identicon",
        "web_url": "https://gitlab.com/aaronsteers"
      },
      "labels": [
        "Accepting Merge Requests",
        "OKR: Improve New User Experience",
        "Windows Support",
        "kind::Bug",
        "valuestream::Meltano"
      ],
      "milestone": {
        "id": 797629,
        "iid": 42,
        "group_id": 2524164,
        "title": "Backlog",
        "description": "As a start, I think it would be good to prioritize based on:\r\n- urgency of getting feedback\r\n- relative implementation difficulty\r\n- symbiotic relationships between issues",
        "state": "active",
        "created_at": "2019-02-21T14:50:28.741Z",
        "updated_at": "2019-02-21T14:50:28.741Z",
        "due_date": null,
        "start_date": "2019-02-25",
        "expired": false,
        "web_url": "https://gitlab.com/groups/meltano/-/milestones/42"
      },
      "assignees": [],
      "author": {
        "id": 4809760,
        "username": "aaronsteers",
        "public_email": "aaronsteers@gmail.com",
        "name": "AJ Steers",
        "state": "active",
        "locked": false,
        "avatar_url": "https://secure.gravatar.com/avatar/a2595480c83e2879745276d7beca618e489d7df97677ed44888fd6f0f50efb29?s=80&d=identicon",
        "web_url": "https://gitlab.com/aaronsteers"
      },
      "type": "ISSUE",
      "assignee": null,
      "user_notes_count": 9,
      "merge_requests_count": 0,
      "upvotes": 0,
      "downvotes": 0,
      "due_date": null,
      "confidential": false,
      "discussion_locked": null,
      "issue_type": "issue",
      "web_url": "https://gitlab.com/meltano/meltano/-/issues/1148",
      "time_stats": {
        "time_estimate": 0,
        "total_time_spent": 0,
        "human_time_estimate": null,
        "human_total_time_spent": null
      },
      "task_completion_status": {
        "count": 2,
        "completed_count": 0
      },
      "weight": null,
      "blocking_issues_count": 0,
      "has_tasks": false,
      "_links": {
        "self": "https://gitlab.com/api/v4/projects/7603319/issues/1148",
        "notes": "https://gitlab.com/api/v4/projects/7603319/issues/1148/notes",
        "award_emoji": "https://gitlab.com/api/v4/projects/7603319/issues/1148/award_emoji",
        "project": "https://gitlab.com/api/v4/projects/7603319",
        "closed_as_duplicate_of": null
      },
      "references": {
        "short": "#1148",
        "relative": "#1148",
        "full": "meltano/meltano#1148"
      },
      "severity": "UNKNOWN",
      "moved_to_id": null,
      "imported": false,
      "imported_from": "none",
      "service_desk_reply_to": null,
      "epic_iid": 115,
      "epic": {
        "id": 329384,
        "iid": 115,
        "title": "Meltano on Windows",
        "url": "/groups/meltano/-/epics/115",
        "group_id": 2524164,
        "human_readable_end_date": "May 31, 2022",
        "human_readable_timestamp": "<strong>Past due</strong>"
      },
      "iteration": null,
      "health_status": null,
      "epic_issue_id": 805943,
      "relative_position": -1539
    }
  ]
}
